Workbook

Sheet 使用说明
A1: Pawlight 图片生成模型评测表（最终执行版）
A3: 评测目标
A4: 任务定义 | B4: 评估模型能否在保留宠物个体身份的前提下，理解用户场景描述，并将宠物自然转化到指定的 Pawlight 动漫场景中。
A5: 正式样本量 | B5: 建议 10 个测试用例 × 3 个候选模型 × 每个条件独立生成 2 次，共 60 张结果图。
A6: 参考图 | B6: 每只宠物可使用 2–3 张固定参考图；同一个测试用例在不同模型中必须使用同一组参考图。
A7: 评分结构 | B7: 宠物身份还原 45分 + 用户场景需求还原 30分 + 动漫风格与融合 10分 + 生成质量与结构正确性 10分 + Pawlight产品适配 5分 = 100分。
A8: 生产可用门槛 | B8: 同时满足：身份≥36/45；场景≥21/30；风格≥7/10；生成质量≥7/10；产品适配≥4/5；总分≥80；且无严重失败。
A9: 严重失败 | B9: 严重失败独立于总分。一旦触发，最终生产判定直接为“严重失败”，但保留各项分数用于分析模型短板。
A10: 评审原则 | B10: 身份特征卡与测试用例必须在查看模型结果前预先填写；建议盲评，评审时尽量隐藏模型名称。
A12: 页签与执行顺序
A13: 1 | B13: 宠物特征卡 | C13: 为 10 只宠物预先记录基础外观和 3 个身份锚点。
A14: 2 | B14: 测试用例 | C14: 为每只宠物定义一条自然语言用户需求，并拆成环境、动作、关键元素、空间关系、氛围、构图。
A15: 3 | B15: 评分标准 | C15: 查看所有细项的权重、0–4/0–5 档位定义和严重失败规则。
A16: 4 | B16: 单图评分 | C16: 对 60 张结果逐张评分；黄色列为人工输入，蓝灰列自动计算。
A17: 5 | B17: 模型汇总 | C17: 填写候选模型名称，自动得到各维度均分、生产可用率、严重失败率、耗时与成本。
A19: 颜色说明
A20: 黄色 | B20: 人工填写
A21: 蓝灰色 | B21: 公式自动计算
A22: 红/黄/绿色 | B22: 条件格式提示风险、临界和通过

Sheet 宠物特征卡
A1: 样本编号 | B1: 宠物类型 | C1: 参考图 | D1: 基础外观特征 | E1: 身份锚点1 | F1: 身份锚点2 | G1: 身份锚点3 | H1: 补充说明
A2: P01 | B2: 狗｜金毛 | D2: 幼年金毛，浅奶油金色中长绒毛；头部圆宽，口鼻较短厚；深色眼睛、黑鼻；双耳自然下垂；整体为偏敦实的幼犬体型。 | E2: 整体毛色为较浅的奶油金色，脸部与口鼻区域更浅，耳部与头顶略深，存在柔和的深浅层次。 | F2: 头脸较圆宽，额头饱满；口鼻部短而宽、轮廓厚实，不是细长型金毛脸。 | G2: 双耳为中等大小的自然垂耳，耳尖圆润，耳毛较长且颜色略深于脸部。 | H2: 当前仅1张参考图，主要呈现头脸、胸前和前肢；后半身与尾巴不可见，不将尾巴或背部花纹作为身份判断依据。
A3: P02 | B3: 猫｜黑猫 | D3: 纯黑短毛猫，毛色均匀；体型紧凑，脸型圆；眼睛很大且呈金黄色，黑色鼻头；双耳直立、呈三角形。 | E3: 一双大而圆的金黄色眼睛，虹膜颜色鲜明，眼睛在脸部占比较高，是最突出的识别特征。 | F3: 全脸及可见身体均为纯黑色，鼻梁、口鼻和胸前均无白斑或其他明显杂色。 | G3: 脸型偏圆、口鼻很短，双耳间距较宽，整体呈明显的圆脸短鼻比例。 | H3: 当前仅1张参考图且为趴卧姿势，四肢与尾巴基本不可见；体型判断以头脸和躯干轮廓为主。
A4: P03 | B4: 猫｜三花猫 | D4: 长毛三花猫，白色为主体，头部与身体分布橘色、深棕黑色不规则色块；胸前和前肢大面积白色；粉色鼻头，双耳直立。 | E4: 脸部左右配色高度不对称：一侧眼周及脸颊以橘色为主，另一侧眼周为大片深棕黑色色块。 | F4: 额头中央至鼻梁存在明显白色纵向区域，将左右两侧彩色脸斑分开，并与白色口鼻区域连成一体。 | G4: 胸前与两只前肢为大面积蓬松白毛，而身体两侧仍可见橘色和深色不规则色块，形成明显三花分布。 | H4: 当前仅1张正面偏全身参考图；尾巴及身体背面不可见，不评价不可见区域的色块分布。
A5: P04 | B5: 狗｜萨摩耶 | D5: 白色萨摩耶幼犬，毛量非常大、全身蓬松；脸型圆，口鼻较短；黑色眼睛和鼻头；小型三角立耳部分被长毛包围，体型偏圆润。 | E5: 全身为高密度纯白长绒毛，尤其脸颊、颈部和胸前毛量很大，形成圆润蓬松的外轮廓。 | F5: 头脸较圆，口鼻短而厚，黑色鼻头在白色脸部中央非常突出，嘴角呈自然上扬的“微笑”轮廓。 | G5: 双耳较小、呈三角形直立，耳根部分被头部绒毛覆盖，耳朵相对脸盘显得短小。 | H5: 当前仅1张正面坐姿参考图，后半身和尾巴展示有限；不把姿势、伸舌等瞬时状态作为身份锚点。
A6: P05 | B6: 狗｜柯基 | D6: 橙白双色柯基，体型敦实，躯干较长、四肢很短；大号三角立耳；背部与头部以橙棕色为主，胸腹、口鼻和四肢末端为白色。 | E6: 脸部中央有明显白色纵向额纹，从额头向下经过鼻梁并连接白色口鼻区域，两侧为橙棕色脸斑。 | F6: 胸前至腹部为大面积白毛，两只前腿及爪部也以白色为主，与橙棕色躯干形成清晰分界。 | G6: 典型但非常鲜明的短腿长身比例，体型偏敦实，同时配有相对头部较大的直立三角耳。 | H6: 当前仅1张全身坐姿参考图，可观察整体比例；尾巴不可见，因此不将尾巴长度或形态作为身份判断依据。
A7: P06 | B7: 狗｜泰迪 | D7: 红棕色泰迪/贵宾犬，浓密卷毛；圆形“泰迪”修剪头型，脸盘饱满；大而深色的圆眼，黑鼻；垂耳与脸部毛发融合，体型小巧紧凑。 | E7: 头部修剪成近圆形轮廓，额顶和两侧脸颊毛量充足，口鼻周围形成明显的圆润“泰迪脸”。 | F7: 双眼非常大且圆、颜色深，眼距相对较宽，与较小的黑色鼻头形成明显的三点式面部比例。 | G7: 耳朵自然下垂并被卷毛覆盖，耳部轮廓与两侧脸颊连成一体，整体脸型不是尖长型。 | H7: 当前仅1张正面近全身参考图；项圈和牵引带属于外部物品，不作为身份特征，也不要求生成结果保留。
A8: P07 | B8: 猫｜奶牛猫 | D8: 黑白长毛奶牛猫，体型较大、毛量丰富；头顶、双耳、背部和身体两侧以黑色为主，胸前、腹部和前肢大面积白色；黄绿色眼睛、粉色鼻头。 | E8: 脸部中央有醒目的白色纵向区域，从额头向下延伸至鼻梁和口鼻；其两侧及头顶为黑色，形成明显黑白“面罩”。 | F8: 胸前、颈部到两只前腿均为大面积蓬松白毛，而肩背和身体两侧为黑色，黑白边界非常鲜明。 | G8: 粉色鼻头位于白色口鼻区域中央，配合黄绿色眼睛和黑色头顶，形成高对比的正脸特征组合。 | H8: 当前仅1张坐姿参考图，尾巴与身体背面信息有限；黑白花纹以可见正脸、胸前和身体侧面为主要评分依据。
A9: P08 | B9: 猫｜暹罗 | D9: 暹罗猫，短毛、奶油色躯干；面部、双耳、四肢末端为深棕色重点色；眼睛为明亮蓝色；脸型偏圆，体型较紧凑。 | E9: 双眼为非常醒目的浅蓝/冰蓝色，眼睛较大、偏圆，是与深色面罩形成强对比的核心识别特征。 | F9: 面部深棕色面罩集中覆盖眼周、鼻梁和口鼻，向额头及两侧脸颊逐渐过渡为较浅的奶油色。 | G9: 双耳及四只脚颜色明显深于躯干，形成“深色耳朵+深色袜子+浅色身体”的重点色分布。 | H9: 当前仅1张正面站姿参考图，可较好观察脸部和前肢；尾巴及身体背侧展示不足，不将其作为关键锚点。
A10: P09 | B10: 狗｜哈士奇 | D10: 黑白哈士奇，毛量较厚；双耳高位直立；两眼为浅蓝色；头顶和眼周为深黑色面罩，口鼻、脸颊和胸前为白色；黑色鼻头。 | E10: 双眼均为浅蓝色，颜色明亮且左右一致，与周围深色眼罩形成强烈对比。 | F10: 额头中央存在明显白色纵向额纹，自头顶向鼻梁延伸，两侧被深黑色头顶和眼罩包围。 | G10: 两眼上方各有浅色“眉斑”，与中央白色额纹、深色眼罩共同形成层次清楚的哈士奇面部花纹。 | H10: 当前仅1张头部近照，身体、四肢和尾巴不可见；本样本重点评估脸部花纹、眼睛和耳型，不据此判断完整体型。
A11: P10 | B11: 猫｜异瞳 | D11: 纯黑短毛猫，体型小而偏瘦，四肢纤细；脸型较窄，双耳大且尖；全身无明显白斑；最突出特征为一金一蓝的异色瞳。 | E11: 明显异色瞳：一只眼为金黄色，另一只眼为亮蓝色，两眼颜色差异清晰且必须同时保留。 | F11: 全身及脸部均为纯黑短毛，鼻头同为黑色，胸前、口鼻和四肢均无可见白斑。 | G11: 脸型偏窄、耳朵相对头部较大且尖，配合偏小偏瘦的幼猫体型，整体轮廓较轻巧。 | H11: 当前仅1张正面偏侧全身参考图；异色瞳是本样本最高优先级身份特征，生成时不要求固定哪只眼出现在画面左/右，以避免镜像问题。

Sheet 测试用例
A1: 用例编号 | B1: 样本编号 | C1: 用户原始场景需求 | D1: 核心环境 | E1: 宠物动作/状态 | F1: 关键场景元素 | G1: 空间关系 | H1: 氛围条件 | I1: 构图/镜头要求 | J1: 场景复杂度 | K1: 备注
A2: C01 | B2: P01 | C2: “它安静地坐在清晨的草地上，周围有一些小野花，阳光刚刚照过来，感觉很舒服。” | D2: 清晨的户外草地 | E2: 宠物安静地坐着，整体状态放松、舒适 | F2: 周围的小野花 | G2: 小野花自然分布在宠物周围；宠物位于草地上 | H2: 清晨；刚升起的柔和阳光；安静、舒服、轻暖 | I2: Pawlight默认：完整展示宠物主体的中景/全身构图，宠物为视觉中心，同时保留足够草地与野花环境 | J2: 简单 | K2: 基础场景用例，主要验证身份保持、静态姿态和基础自然光表现
A3: C02 | B3: P02 | C3: “它趴在山坡的草地上看星星，旁边放着一盏暖黄色的小灯。” | D3: 夜晚的山坡草地与星空 | E3: 宠物趴在草坡上，抬头/看向星空，状态安静 | F3: 星空；一盏暖黄色小灯 | G3: 暖黄色小灯位于宠物身旁；宠物趴在山坡草地上，星空位于远景/上方 | H3: 夜晚；冷色星空与暖色灯光形成对比；宁静 | I3: 中景或全身构图，宠物与身旁小灯同时清晰可见，并保留足够星空作为背景 | J3: 中等 | K3: 同时测试黑色宠物在暗光环境下的身份细节保持与夜景融合
A4: C03 | B4: P03 | C4: “它坐在海边的小木屋门口看日落，旁边放着一个黄色网球，温暖、安静一点。” | D4: 海边的小木屋门口，远处可见日落 | E4: 宠物坐在木屋门口，看向日落，状态安静 | F4: 海边小木屋；黄色网球；日落 | G4: 宠物位于小木屋门口；黄色网球放在宠物身旁；海面与日落处于远景 | H4: 日落暖光；温暖、安静、柔和 | I4: 中景/全身构图，宠物为主体，同时清楚呈现木屋门口、黄色网球及海边日落 | J4: 中等 | K4: 测试复杂花纹宠物在建筑+海景+私人道具组合场景中的保持与指令执行
A5: C04 | B5: P04 | C5: “它趴在木屋的窗边晒下午的太阳，窗外可以看到绿色花园，旁边放着它的小毯子。” | D5: 木屋室内的窗边，窗外是绿色花园 | E5: 宠物趴在窗边晒下午的太阳，状态放松 | F5: 窗户；绿色花园；宠物的小毯子 | G5: 宠物趴在窗边；小毯子位于宠物旁边；绿色花园位于窗外 | H5: 下午；柔和自然阳光；温暖、居家、舒适 | I5: 中景/全身构图，宠物与小毯子为近景主体，同时通过窗户清楚看到外部花园 | J5: 中等 | K5: 测试室内外双空间、窗边光照以及白色长毛在亮部环境中的轮廓保持
A6: C05 | B6: P05 | C6: “它在刚下过雪的松树林里慢慢往前走，地上有脚印，远处能看到一间亮着灯的小木屋。” | D6: 刚下过雪的松树林 | E6: 宠物缓慢向前行走，动作自然 | F6: 雪地脚印；松树；远处亮着灯的小木屋 | G6: 宠物走在雪地中；脚印沿其行走路径留在地面；亮灯小木屋位于远处背景 | H6: 雪后安静环境；整体偏冷，远处木屋暖光形成冷暖对比 | I6: 全身中远景，需完整展示行走姿态、雪地脚印，并在远景保留亮灯木屋 | J6: 复杂 | K6: 重点测试动态姿态、短腿体型保持、雪地重复纹理和远近层次
A7: C06 | B7: P06 | C7: “它在开满花的小花园里追一只蝴蝶，动作自然一点，像平时玩耍的样子。” | D7: 开满花的小花园 | E7: 宠物自然地追逐一只蝴蝶，呈玩耍状态 | F7: 大量花朵；一只蝴蝶 | G7: 蝴蝶位于宠物追逐方向的前方或稍上方；宠物在花园中运动 | H7: 白天；自然、轻快、有生活感，但不过度夸张兴奋 | I7: 全身动态构图，给宠物运动方向留出空间，同时清楚呈现蝴蝶与花园环境 | J7: 复杂 | K7: 重点测试卷毛宠物在动态动作、复杂花卉背景和小目标互动中的稳定性
A8: C07 | B8: P07 | C8: “它坐在湖边的木栈道上看远处的山，身旁放着一个小水碗，水面比较平静。” | D8: 湖边的木栈道，远处有山 | E8: 宠物坐在木栈道上看向远处的山，状态平静 | F8: 木栈道；湖面；远山；一个小水碗 | G8: 宠物位于木栈道上；水碗放在宠物身旁；湖面位于前/中景，远山处于背景 | H8: 平静水面；安静、舒缓的自然氛围 | I8: 中景或中远景，完整展示宠物和水碗，同时保留湖面与远山的空间层次 | J8: 中等 | K8: 测试高对比黑白花纹、道具空间关系以及水面和远景层次
A9: C08 | B9: P08 | C9: “它沿着秋天的森林小路慢慢散步，地上都是金黄色的落叶，偶尔回头看向我。” | D9: 秋天的森林小路 | E9: 宠物沿小路慢慢散步，并回头看向用户/镜头 | F9: 金黄色落叶；森林小路 | G9: 宠物位于小路上向前行走，同时头部回转看向后方/镜头；落叶铺在地面 | H9: 秋季；金黄色调；安静、自然、略带温暖感 | I9: 全身三分之四侧后方动态构图，既体现前行方向，又清楚看到回头后的脸部 | J9: 复杂 | K9: 重点测试非正面视角下的身份保持、回头动作和高密度落叶纹理
A10: C09 | B10: P09 | C10: “它坐在自己的小星球上，周围有一些柔和发光的植物，远处能看到星空和其他小星球，感觉像它在那里安静生活。” | D10: 宠物自己的小星球，周围是星空与其他小星球 | E10: 宠物安静地坐在自己的小星球上，呈自然生活状态 | F10: 柔和发光的植物；远处星空；其他小星球 | G10: 发光植物分布在宠物周围；宠物位于小星球表面；其他小星球位于远处背景 | H10: 夜晚幻想环境；柔和发光；宁静、温暖、有陪伴感 | I10: 中远景，宠物保持为清晰主体，同时能看出“小星球”整体环境及远处星空层次 | J10: 复杂 | K10: Pawlight核心世界观用例，测试幻想场景、非现实光源与宠物身份/风格融合
A11: C10 | B11: P10 | C11: “像从一个观察窗里看到它一样，它正在自己的小屋门口休息，旁边有喜欢的玩具和几株植物，远处是星空，画面有生活感。” | D11: 从观察窗视角看到的宠物小屋门口，远处为星空 | E11: 宠物在自己的小屋门口自然休息，状态松弛、有生活感 | F11: 宠物小屋；喜欢的玩具；几株植物；远处星空 | G11: 宠物位于小屋门口；玩具和植物分布在宠物身旁；星空位于远处背景 | H11: 夜晚；安静、温暖、日常、有持续生活感 | I11: 明确采用“观察窗”视角的中景/中远景构图，宠物与小屋门口为视觉核心，同时保留前后景层次 | J11: 复杂 | K11: 综合用例：同时检验特殊身份特征、建筑、多元素、空间关系及Pawlight最终产品展示形态

Sheet 评分标准
A1: 一级维度 | B1: 二级指标 | C1: 权重 | D1: 原始满分 | E1: 0分 | F1: 1分 | G1: 2分 | H1: 3分 | I1: 4分 | J1: 5分 | K1: 主要观察点 | L1: 权重/规则说明
A2: 宠物身份还原 | B2: 身份锚点1 | C2: 4 | D2: 5 | E2: 完全缺失或相反 | F2: 几乎消失，仅勉强存在类似元素 | G2: 只保留大致概念，已不是原特征 | H2: 特征存在，但位置/面积/形态明显变化 | I2: 清楚保留，仅轻微偏差 | J2: 完整保留，位置和形态基本一致 | K2: 预先定义的个体关键特征 | L2: 身份锚点共12分，是“是不是这只宠物”的最直接信号
A3: 宠物身份还原 | B3: 身份锚点2 | C3: 4 | D3: 5 | E3: 完全缺失或相反 | F3: 几乎消失，仅勉强存在类似元素 | G3: 只保留大致概念，已不是原特征 | H3: 特征存在，但位置/面积/形态明显变化 | I3: 清楚保留，仅轻微偏差 | J3: 完整保留，位置和形态基本一致 | K3: 预先定义的个体关键特征 | L3: 同上
A4: 宠物身份还原 | B4: 身份锚点3 | C4: 4 | D4: 5 | E4: 完全缺失或相反 | F4: 几乎消失，仅勉强存在类似元素 | G4: 只保留大致概念，已不是原特征 | H4: 特征存在，但位置/面积/形态明显变化 | I4: 清楚保留，仅轻微偏差 | J4: 完整保留，位置和形态基本一致 | K4: 预先定义的个体关键特征 | L4: 同上
A5: 宠物身份还原 | B5: 头脸结构 | C5: 8 | D5: 4 | E5: 头脸类型明显错误 | F5: 只有粗略品种特征一致 | G5: 类似类型，但个体脸型明显泛化 | H5: 整体一致，局部比例有偏差 | I5: 头脸比例、脸型、口鼻结构高度一致 | J5: 48 | K5: 脸长宽、额头、口鼻长度、眼距、颊部、下巴 | L5: 猫狗个体识别中最重要的稳定区域之一
A6: 宠物身份还原 | B6: 毛色 | C6: 5 | D6: 4 | E6: 主体毛色错误 | F6: 仅深浅色等粗粒度一致 | G6: 颜色类型大致正确，但色调/覆盖比例明显不同 | H6: 主色正确，次色或深浅轻微偏差 | I6: 主色、次色和整体色调基本一致 | J6: 48 | K6: 主色、次色、深浅、颜色占比 | L6: 重要，但单独不能证明个体身份
A7: 宠物身份还原 | B7: 花纹与色块分布 | C7: 6 | D7: 4 | E7: 主要花纹消失或完全改变 | F7: 仅保留“有花纹/虎斑”等类别特征 | G7: 花纹类型正确，但位置/范围明显改变 | H7: 整体结构正确，少量局部偏差 | I7: 主要花纹位置、范围、关系基本一致 | J7: 48 | K7: 色块位置、大小、数量、左右关系、条纹/斑点 | L7: 对花猫、花狗等个体识别贡献高
A8: 宠物身份还原 | B8: 体型与身体比例 | C8: 4 | D8: 4 | E8: 体型类别明显错误 | F8: 只保留品种常见体型 | G8: 大小类型正确，但比例明显变化 | H8: 整体体型正确，仅轻微胖瘦/比例变化 | I8: 体型、胖瘦、头身比、四肢比例基本一致 | J8: 48 | K8: 胖瘦、躯干、腿长、胸宽、头身比、尾巴比例 | L8: 用于区分“同品种的另一只宠物”
A9: 宠物身份还原 | B9: 耳朵 | C9: 4 | D9: 4 | E9: 耳型错误 | F9: 只有品种常见耳型一致 | G9: 同类耳型但明显泛化 | H9: 类型一致，比例或角度略有变化 | I9: 形状、大小、状态、位置高度一致 | J9: 48 | K9: 立/折/垂耳、大小、角度、左右差异 | L9: 猫狗高辨识度局部特征
A10: 宠物身份还原 | B10: 眼睛/鼻子/口鼻部 | C10: 4 | D10: 4 | E10: 主要特征明显错误 | F10: 只保留泛化品种特征 | G10: 类别正确但个体差异明显 | H10: 大部分一致，有轻微细节偏差 | I10: 主要可观察特征基本一致 | J10: 48 | K10: 眼色眼型、鼻色鼻型、口鼻部色块 | L10: 辨识力较高，但受参考图清晰度影响
A11: 宠物身份还原 | B11: 品种/毛发类型 | C11: 2 | D11: 4 | E11: 品种或毛发类型明显错误 | F11: 只能识别为类似类型 | G11: 品种大致正确，毛发特征明显不同 | H11: 基本一致，毛量/长度略有变化 | I11: 品种与毛发类型一致 | J11: 48 | K11: 长短毛、卷直、毛量、基础品种表型 | L11: Pawlight判断的是个体而不是品种，因此权重较低
A12: 用户场景需求还原 | B12: 核心环境 | C12: 7 | D12: 4 | E12: 核心环境完全错误或冲突 | F12: 仅有少量相关元素，整体环境偏离 | G12: 只还原部分场景语义，地点大类接近 | H12: 核心地点正确，缺少次级环境特征或有偏差 | I12: 核心地点及主要环境特征完整正确 | J12: 48 | K12: 用户要求宠物身处的地点/环境 | L12: 权重最高，直接决定用户想象中的世界是否被建立
A13: 用户场景需求还原 | B13: 宠物动作/状态 | C13: 6 | D13: 4 | E13: 核心动作完全错误或相反 | F13: 只有粗略动作类别相近 | G13: 部分动作要求满足，但行为表达不完整 | H13: 核心动作正确，朝向/状态轻微偏差 | I13: 核心动作、朝向、姿态、状态基本正确 | J13: 48 | K13: 坐、趴、跑、回头、看向远处、安静等 | L13: 宠物在场景中“正在做什么”是核心叙事
... A25: Pawlight产品适配 | B25: 世界观一致性 | C25: 2 | D25: 4 | E25: 与Pawlight世界观完全冲突 | F25: 明显偏纪念海报/宠物写真等其他形态 | G25: 可作为宠物图，但缺乏另一个生活世界的表达 | H25: 整体符合，仅略偏普通宠物插画 | I25: 宠物自然生活在场景中，有“TA在那里继续生活”的感觉 | J25: 48 | K25: 宠物是场景中的居民，而非静止纪念物 | L25: 体现Pawlight区别于传统纪念海报的产品表达
A28: 严重失败（一票否决）规则
A29: 身份严重失败 | B29: 物种错误；品种完全错误；主要毛色完全错误；多个关键身份特征完全丢失
A30: 场景严重失败 | B30: 核心环境完全错误；核心纪念元素完全错误/缺失，导致用户需求含义被改变
A31: 结构严重失败 | B31: 明显多肢/少肢/多头；面部严重崩坏；身体严重融合、断裂或无法合理解释
A32: 产品语义严重失败 | B32: 未经要求主动生成墓碑/墓地/RIP等死亡核心叙事；尸体/伤口/明显病痛；恐怖/极端痛苦；强烈宗教或升天叙事；完全拟人化导致宠物身份消失
A33: 判定原则 | B33: 严重失败独立于100分评分。一旦触发，生产判定直接为“严重失败”；用户主动提出的翅膀、云端等内容不因本项自动处罚。

Sheet 单图评分 -GPT
A1: 记录编号 | B1: 用例编号 | C1: 样本编号 | D1: 模型 | E1: 模型版本 | F1: 生成轮次 | G1: 结果文件 | H1: 评审人 | I1: 锚点1 0-5 | J1: 锚点2 0-5 | K1: 锚点3 0-5 | L1: 头脸结构 0-4 | M1: 毛色 0-4 | N1: 花纹色块 0-4 | O1: 体型比例 0-4 | P1: 耳朵 0-4 | Q1: 眼鼻口 0-4 | R1: 品种毛发 0-4 | S1: 身份还原 /45 | T1: 核心环境 0-4 | U1: 动作状态 0-4 | V1: 关键元素 0-4 | W1: 空间关系 0-4 | X1: 氛围条件 0-4 | Y1: 构图镜头 0-4 | Z1: 场景还原 /30 | AA1: 目标动漫风格 0-4 | AB1: 风格一致 0-4 | AC1: 融合自然 0-4 | AD1: 动漫风格与融合 /10 | AE1: 身体结构 0-4 | AF1: 面部局部 0-4 | AG1: 生成瑕疵 0-4 | AH1: 生成质量 /10 | AI1: 纪念语义边界 0-4 | AJ1: 世界观一致 0-4 | AK1: 产品适配 /5 | AL1: 总分 /100 | AM1: 严重失败类型 | AN1: 严重失败？ | AO1: 身份判定 | AP1: 场景判定 | AQ1: 风格判定 | AR1: 质量判定 | AS1: 产品判定 | AT1: 生产判定 | AU1: 生成耗时（秒） | AV1: 单次成本（元） | AW1: 备注
A2: R001 | B2: C01 | C2: P01 | D2: Nano Banana | E2: 3 Lite | F2: 第一轮 | I2: 4 | J2: 4 | K2: 5 | L2: 4 | M2: 4 | N2: 4 | O2: 4 | P2: 4 | Q2: 4 | R2: 4 | S2: =IF(COUNTA(I2:R2)=0,"",I2/5*4+J2/5*4+K2/5*4+L2/4*8+M2/4*5+N2/4*6+O2/4*4+P2/4*4+Q2/4*4+R2/4*2) -> 43.4 | T2: 4 | U2: 4 | V2: 4 | W2: 4 | X2: 4 | Y2: 4 | Z2: =IF(COUNTA(T2:Y2)=0,"",T2/4*7+U2/4*6+V2/4*6+W2/4*4+X2/4*4+Y2/4*3) -> 30 | AA2: 4 | AB2: 4 | AC2: 4 | AD2: =IF(COUNTA(AA2:AC2)=0,"",AA2/4*4+AB2/4*3+AC2/4*3) -> 10 | AE2: 4 | AF2: 4 | AG2: 4 | AH2: =IF(COUNTA(AE2:AG2)=0,"",AE2/4*4+AF2/4*3+AG2/4*3) -> 10 | AI2: 4 | AJ2: 3 | AK2: =IF(COUNTA(AI2:AJ2)=0,"",AI2/4*3+AJ2/4*2) -> 4.5 | AL2: =IF(COUNTA(S2,Z2,AD2,AH2,AK2)<5,"",SUM(S2,Z2,AD2,AH2,AK2)) -> 97.9 | AN2: =IF(AM2="","否","是") -> 否 | AO2: =IF(S2="","",IF(S2>=36,"合格",IF(S2>=31.5,"临界","不合格"))) -> 合格 | AP2: =IF(Z2="","",IF(Z2>=21,"合格",IF(Z2>=18,"临界","不合格"))) -> 合格 | AQ2: =IF(AD2="","",IF(AD2>=7,"合格",IF(AD2>=6,"临界","不合格"))) -> 合格 | AR2: =IF(AH2="","",IF(AH2>=7,"合格",IF(AH2>=6,"临界","不合格"))) -> 合格 | AS2: =IF(AK2="","",IF(AK2>=4,"合格",IF(AK2>=3,"临界","不合格"))) -> 合格 | AT2: =IF(AL2="","",IF(AN2="是","严重失败",IF(AND(S2>=36,Z2>=21,AD2>=7,AH2>=7,AK2>=4,AL2>=80),"生产可用",IF(OR(S2<31.5,Z2<18,AD2<6,AH2<6,AK2<3),"不可用","待复核")))) -> 生产可用
A3: R002 | B3: C01 | C3: P01 | D3: Nano Banana | E3: 3 Lite | F3: 第二轮 | I3: 4 | J3: 4 | K3: 5 | L3: 4 | M3: 4 | N3: 4 | O3: 4 | P3: 4 | Q3: 4 | R3: 4 | S3: =IF(COUNTA(I3:R3)=0,"",I3/5*4+J3/5*4+K3/5*4+L3/4*8+M3/4*5+N3/4*6+O3/4*4+P3/4*4+Q3/4*4+R3/4*2) -> 43.4 | T3: 4 | U3: 4 | V3: 4 | W3: 4 | X3: 4 | Y3: 4 | Z3: =IF(COUNTA(T3:Y3)=0,"",T3/4*7+U3/4*6+V3/4*6+W3/4*4+X3/4*4+Y3/4*3) -> 30 | AA3: 4 | AB3: 4 | AC3: 4 | AD3: =IF(COUNTA(AA3:AC3)=0,"",AA3/4*4+AB3/4*3+AC3/4*3) -> 10 | AE3: 4 | AF3: 4 | AG3: 4 | AH3: =IF(COUNTA(AE3:AG3)=0,"",AE3/4*4+AF3/4*3+AG3/4*3) -> 10 | AI3: 4 | AJ3: 3 | AK3: =IF(COUNTA(AI3:AJ3)=0,"",AI3/4*3+AJ3/4*2) -> 4.5 | AL3: =IF(COUNTA(S3,Z3,AD3,AH3,AK3)<5,"",SUM(S3,Z3,AD3,AH3,AK3)) -> 97.9 | AN3: =IF(AM3="","否","是") -> 否 | AO3: =IF(S3="","",IF(S3>=36,"合格",IF(S3>=31.5,"临界","不合格"))) -> 合格 | AP3: =IF(Z3="","",IF(Z3>=21,"合格",IF(Z3>=18,"临界","不合格"))) -> 合格 | AQ3: =IF(AD3="","",IF(AD3>=7,"合格",IF(AD3>=6,"临界","不合格"))) -> 合格 | AR3: =IF(AH3="","",IF(AH3>=7,"合格",IF(AH3>=6,"临界","不合格"))) -> 合格 | AS3: =IF(AK3="","",IF(AK3>=4,"合格",IF(AK3>=3,"临界","不合格"))) -> 合格 | AT3: =IF(AL3="","",IF(AN3="是","严重失败",IF(AND(S3>=36,Z3>=21,AD3>=7,AH3>=7,AK3>=4,AL3>=80),"生产可用",IF(OR(S3<31.5,Z3<18,AD3<6,AH3<6,AK3<3),"不可用","待复核")))) -> 生产可用
A4: R003 | B4: C01 | C4: P01 | D4: Seedream | E4: 5.0 flash | F4: 第一轮 | I4: 4 | J4: 3 | K4: 4 | L4: 3 | M4: 4 | N4: 4 | O4: 3 | P4: 4 | Q4: 4 | R4: 2 | S4: =IF(COUNTA(I4:R4)=0,"",I4/5*4+J4/5*4+K4/5*4+L4/4*8+M4/4*5+N4/4*6+O4/4*4+P4/4*4+Q4/4*4+R4/4*2) -> 37.8 | T4: 4 | U4: 4 | V4: 4 | W4: 4 | X4: 3 | Y4: 4 | Z4: =IF(COUNTA(T4:Y4)=0,"",T4/4*7+U4/4*6+V4/4*6+W4/4*4+X4/4*4+Y4/4*3) -> 29 | AA4: 3 | AB4: 3 | AC4: 3 | AD4: =IF(COUNTA(AA4:AC4)=0,"",AA4/4*4+AB4/4*3+AC4/4*3) -> 7.5 | AE4: 4 | AF4: 4 | AG4: 4 | AH4: =IF(COUNTA(AE4:AG4)=0,"",AE4/4*4+AF4/4*3+AG4/4*3) -> 10 | AI4: 4 | AJ4: 3 | AK4: =IF(COUNTA(AI4:AJ4)=0,"",AI4/4*3+AJ4/4*2) -> 4.5 | AL4: =IF(COUNTA(S4,Z4,AD4,AH4,AK4)<5,"",SUM(S4,Z4,AD4,AH4,AK4)) -> 88.8 | AN4: =IF(AM4="","否","是") -> 否 | AO4: =IF(S4="","",IF(S4>=36,"合格",IF(S4>=31.5,"临界","不合格"))) -> 合格 | AP4: =IF(Z4="","",IF(Z4>=21,"合格",IF(Z4>=18,"临界","不合格"))) -> 合格 | AQ4: =IF(AD4="","",IF(AD4>=7,"合格",IF(AD4>=6,"临界","不合格"))) -> 合格 | AR4: =IF(AH4="","",IF(AH4>=7,"合格",IF(AH4>=6,"临界","不合格"))) -> 合格 | AS4: =IF(AK4="","",IF(AK4>=4,"合格",IF(AK4>=3,"临界","不合格"))) -> 合格 | AT4: =IF(AL4="","",IF(AN4="是","严重失败",IF(AND(S4>=36,Z4>=21,AD4>=7,AH4>=7,AK4>=4,AL4>=80),"生产可用",IF(OR(S4<31.5,Z4<18,AD4<6,AH4<6,AK4<3),"不可用","待复核")))) -> 生产可用
A5: R004 | B5: C01 | C5: P01 | D5: Seedream | E5: 5.0 flash | F5: 第二轮 | I5: 4 | J5: 3 | K5: 4 | L5: 3 | M5: 4 | N5: 4 | O5: 3 | P5: 4 | Q5: 4 | R5: 3 | S5: =IF(COUNTA(I5:R5)=0,"",I5/5*4+J5/5*4+K5/5*4+L5/4*8+M5/4*5+N5/4*6+O5/4*4+P5/4*4+Q5/4*4+R5/4*2) -> 38.3 | T5: 4 | U5: 4 | V5: 4 | W5: 4 | X5: 4 | Y5: 4 | Z5: =IF(COUNTA(T5:Y5)=0,"",T5/4*7+U5/4*6+V5/4*6+W5/4*4+X5/4*4+Y5/4*3) -> 30 | AA5: 3 | AB5: 3 | AC5: 3 | AD5: =IF(COUNTA(AA5:AC5)=0,"",AA5/4*4+AB5/4*3+AC5/4*3) -> 7.5 | AE5: 4 | AF5: 4 | AG5: 4 | AH5: =IF(COUNTA(AE5:AG5)=0,"",AE5/4*4+AF5/4*3+AG5/4*3) -> 10 | AI5: 4 | AJ5: 3 | AK5: =IF(COUNTA(AI5:AJ5)=0,"",AI5/4*3+AJ5/4*2) -> 4.5 | AL5: =IF(COUNTA(S5,Z5,AD5,AH5,AK5)<5,"",SUM(S5,Z5,AD5,AH5,AK5)) -> 90.3 | AN5: =IF(AM5="","否","是") -> 否 | AO5: =IF(S5="","",IF(S5>=36,"合格",IF(S5>=31.5,"临界","不合格"))) -> 合格 | AP5: =IF(Z5="","",IF(Z5>=21,"合格",IF(Z5>=18,"临界","不合格"))) -> 合格 | AQ5: =IF(AD5="","",IF(AD5>=7,"合格",IF(AD5>=6,"临界","不合格"))) -> 合格 | AR5: =IF(AH5="","",IF(AH5>=7,"合格",IF(AH5>=6,"临界","不合格"))) -> 合格 | AS5: =IF(AK5="","",IF(AK5>=4,"合格",IF(AK5>=3,"临界","不合格"))) -> 合格 | AT5: =IF(AL5="","",IF(AN5="是","严重失败",IF(AND(S5>=36,Z5>=21,AD5>=7,AH5>=7,AK5>=4,AL5>=80),"生产可用",IF(OR(S5<31.5,Z5<18,AD5<6,AH5<6,AK5<3),"不可用","待复核")))) -> 生产可用
A6: R005 | B6: C01 | C6: P01 | D6: GPT image | E6: 2.5 | F6: 第一轮 | I6: 3 | J6: 3 | K6: 4 | L6: 3 | M6: 3 | N6: 3 | O6: 4 | P6: 4 | Q6: 4 | R6: 4 | S6: =IF(COUNTA(I6:R6)=0,"",I6/5*4+J6/5*4+K6/5*4+L6/4*8+M6/4*5+N6/4*6+O6/4*4+P6/4*4+Q6/4*4+R6/4*2) -> 36.25 | T6: 4 | U6: 4 | V6: 4 | W6: 4 | X6: 4 | Y6: 4 | Z6: =IF(COUNTA(T6:Y6)=0,"",T6/4*7+U6/4*6+V6/4*6+W6/4*4+X6/4*4+Y6/4*3) -> 30 | AA6: 0 | AB6: 4 | AC6: 4 | AD6: =IF(COUNTA(AA6:AC6)=0,"",AA6/4*4+AB6/4*3+AC6/4*3) -> 6 | AE6: 4 | AF6: 4 | AG6: 4 | AH6: =IF(COUNTA(AE6:AG6)=0,"",AE6/4*4+AF6/4*3+AG6/4*3) -> 10 | AI6: 4 | AJ6: 3 | AK6: =IF(COUNTA(AI6:AJ6)=0,"",AI6/4*3+AJ6/4*2) -> 4.5 | AL6: =IF(COUNTA(S6,Z6,AD6,AH6,AK6)<5,"",SUM(S6,Z6,AD6,AH6,AK6)) -> 86.75 | AN6: =IF(AM6="","否","是") -> 否 | AO6: =IF(S6="","",IF(S6>=36,"合格",IF(S6>=31.5,"临界","不合格"))) -> 合格 | AP6: =IF(Z6="","",IF(Z6>=21,"合格",IF(Z6>=18,"临界","不合格"))) -> 合格 | AQ6: =IF(AD6="","",IF(AD6>=7,"合格",IF(AD6>=6,"临界","不合格"))) -> 临界 | AR6: =IF(AH6="","",IF(AH6>=7,"合格",IF(AH6>=6,"临界","不合格"))) -> 合格 | AS6: =IF(AK6="","",IF(AK6>=4,"合格",IF(AK6>=3,"临界","不合格"))) -> 合格 | AT6: =IF(AL6="","",IF(AN6="是","严重失败",IF(AND(S6>=36,Z6>=21,AD6>=7,AH6>=7,AK6>=4,AL6>=80),"生产可用",IF(OR(S6<31.5,Z6<18,AD6<6,AH6<6,AK6<3),"不可用","待复核")))) -> 待复核
A7: R006 | B7: C01 | C7: P01 | D7: GPT image | E7: 2.5 | F7: 第二轮 | I7: 3 | J7: 3 | K7: 4 | L7: 3 | M7: 3 | N7: 3 | O7: 4 | P7: 4 | Q7: 4 | R7: 4 | S7: =IF(COUNTA(I7:R7)=0,"",I7/5*4+J7/5*4+K7/5*4+L7/4*8+M7/4*5+N7/4*6+O7/4*4+P7/4*4+Q7/4*4+R7/4*2) -> 36.25 | T7: 4 | U7: 4 | V7: 4 | W7: 4 | X7: 4 | Y7: 4 | Z7: =IF(COUNTA(T7:Y7)=0,"",T7/4*7+U7/4*6+V7/4*6+W7/4*4+X7/4*4+Y7/4*3) -> 30 | AA7: 0 | AB7: 4 | AC7: 4 | AD7: =IF(COUNTA(AA7:AC7)=0,"",AA7/4*4+AB7/4*3+AC7/4*3) -> 6 | AE7: 4 | AF7: 4 | AG7: 4 | AH7: =IF(COUNTA(AE7:AG7)=0,"",AE7/4*4+AF7/4*3+AG7/4*3) -> 10 | AI7: 4 | AJ7: 3 | AK7: =IF(COUNTA(AI7:AJ7)=0,"",AI7/4*3+AJ7/4*2) -> 4.5 | AL7: =IF(COUNTA(S7,Z7,AD7,AH7,AK7)<5,"",SUM(S7,Z7,AD7,AH7,AK7)) -> 86.75 | AN7: =IF(AM7="","否","是") -> 否 | AO7: =IF(S7="","",IF(S7>=36,"合格",IF(S7>=31.5,"临界","不合格"))) -> 合格 | AP7: =IF(Z7="","",IF(Z7>=21,"合格",IF(Z7>=18,"临界","不合格"))) -> 合格 | AQ7: =IF(AD7="","",IF(AD7>=7,"合格",IF(AD7>=6,"临界","不合格"))) -> 临界 | AR7: =IF(AH7="","",IF(AH7>=7,"合格",IF(AH7>=6,"临界","不合格"))) -> 合格 | AS7: =IF(AK7="","",IF(AK7>=4,"合格",IF(AK7>=3,"临界","不合格"))) -> 合格 | AT7: =IF(AL7="","",IF(AN7="是","严重失败",IF(AND(S7>=36,Z7>=21,AD7>=7,AH7>=7,AK7>=4,AL7>=80),"生产可用",IF(OR(S7<31.5,Z7<18,AD7<6,AH7<6,AK7<3),"不可用","待复核")))) -> 待复核
A8: R007 | B8: C02 | C8: P02 | D8: Nano Banana | E8: 3 Lite | F8: 第一轮 | I8: 5 | J8: 5 | K8: 5 | L8: 4 | M8: 4 | N8: 4 | O8: 4 | P8: 4 | Q8: 4 | R8: 4 | S8: =IF(COUNTA(I8:R8)=0,"",I8/5*4+J8/5*4+K8/5*4+L8/4*8+M8/4*5+N8/4*6+O8/4*4+P8/4*4+Q8/4*4+R8/4*2) -> 45 | T8: 4 | U8: 4 | V8: 4 | W8: 4 | X8: 4 | Y8: 4 | Z8: =IF(COUNTA(T8:Y8)=0,"",T8/4*7+U8/4*6+V8/4*6+W8/4*4+X8/4*4+Y8/4*3) -> 30 | AA8: 4 | AB8: 4 | AC8: 4 | AD8: =IF(COUNTA(AA8:AC8)=0,"",AA8/4*4+AB8/4*3+AC8/4*3) -> 10 | AE8: 4 | AF8: 4 | AG8: 4 | AH8: =IF(COUNTA(AE8:AG8)=0,"",AE8/4*4+AF8/4*3+AG8/4*3) -> 10 | AI8: 4 | AJ8: 3 | AK8: =IF(COUNTA(AI8:AJ8)=0,"",AI8/4*3+AJ8/4*2) -> 4.5 | AL8: =IF(COUNTA(S8,Z8,AD8,AH8,AK8)<5,"",SUM(S8,Z8,AD8,AH8,AK8)) -> 99.5 | AN8: =IF(AM8="","否","是") -> 否 | AO8: =IF(S8="","",IF(S8>=36,"合格",IF(S8>=31.5,"临界","不合格"))) -> 合格 | AP8: =IF(Z8="","",IF(Z8>=21,"合格",IF(Z8>=18,"临界","不合格"))) -> 合格 | AQ8: =IF(AD8="","",IF(AD8>=7,"合格",IF(AD8>=6,"临界","不合格"))) -> 合格 | AR8: =IF(AH8="","",IF(AH8>=7,"合格",IF(AH8>=6,"临界","不合格"))) -> 合格 | AS8: =IF(AK8="","",IF(AK8>=4,"合格",IF(AK8>=3,"临界","不合格"))) -> 合格 | AT8: =IF(AL8="","",IF(AN8="是","严重失败",IF(AND(S8>=36,Z8>=21,AD8>=7,AH8>=7,AK8>=4,AL8>=80),"生产可用",IF(OR(S8<31.5,Z8<18,AD8<6,AH8<6,AK8<3),"不可用","待复核")))) -> 生产可用
A9: R008 | B9: C02 | C9: P02 | D9: Nano Banana | E9: 3 Lite | F9: 第二轮 | I9: 5 | J9: 5 | K9: 5 | L9: 4 | M9: 4 | N9: 4 | O9: 4 | P9: 4 | Q9: 4 | R9: 4 | S9: =IF(COUNTA(I9:R9)=0,"",I9/5*4+J9/5*4+K9/5*4+L9/4*8+M9/4*5+N9/4*6+O9/4*4+P9/4*4+Q9/4*4+R9/4*2) -> 45 | T9: 4 | U9: 4 | V9: 4 | W9: 4 | X9: 4 | Y9: 4 | Z9: =IF(COUNTA(T9:Y9)=0,"",T9/4*7+U9/4*6+V9/4*6+W9/4*4+X9/4*4+Y9/4*3) -> 30 | AA9: 4 | AB9: 4 | AC9: 4 | AD9: =IF(COUNTA(AA9:AC9)=0,"",AA9/4*4+AB9/4*3+AC9/4*3) -> 10 | AE9: 4 | AF9: 4 | AG9: 4 | AH9: =IF(COUNTA(AE9:AG9)=0,"",AE9/4*4+AF9/4*3+AG9/4*3) -> 10 | AI9: 4 | AJ9: 3 | AK9: =IF(COUNTA(AI9:AJ9)=0,"",AI9/4*3+AJ9/4*2) -> 4.5 | AL9: =IF(COUNTA(S9,Z9,AD9,AH9,AK9)<5,"",SUM(S9,Z9,AD9,AH9,AK9)) -> 99.5 | AN9: =IF(AM9="","否","是") -> 否 | AO9: =IF(S9="","",IF(S9>=36,"合格",IF(S9>=31.5,"临界","不合格"))) -> 合格 | AP9: =IF(Z9="","",IF(Z9>=21,"合格",IF(Z9>=18,"临界","不合格"))) -> 合格 | AQ9: =IF(AD9="","",IF(AD9>=7,"合格",IF(AD9>=6,"临界","不合格"))) -> 合格 | AR9: =IF(AH9="","",IF(AH9>=7,"合格",IF(AH9>=6,"临界","不合格"))) -> 合格 | AS9: =IF(AK9="","",IF(AK9>=4,"合格",IF(AK9>=3,"临界","不合格"))) -> 合格 | AT9: =IF(AL9="","",IF(AN9="是","严重失败",IF(AND(S9>=36,Z9>=21,AD9>=7,AH9>=7,AK9>=4,AL9>=80),"生产可用",IF(OR(S9<31.5,Z9<18,AD9<6,AH9<6,AK9<3),"不可用","待复核")))) -> 生产可用
A10: R009 | B10: C02 | C10: P02 | D10: Seedream | E10: 5.0 flash | F10: 第一轮 | I10: 3 | J10: 5 | K10: 3 | L10: 3 | M10: 4 | N10: 4 | O10: 3 | P10: 4 | Q10: 3 | R10: 4 | S10: =IF(COUNTA(I10:R10)=0,"",I10/5*4+J10/5*4+K10/5*4+L10/4*8+M10/4*5+N10/4*6+O10/4*4+P10/4*4+Q10/4*4+R10/4*2) -> 37.8 | T10: 4 | U10: 4 | V10: 4 | W10: 4 | X10: 4 | Y10: 4 | Z10: =IF(COUNTA(T10:Y10)=0,"",T10/4*7+U10/4*6+V10/4*6+W10/4*4+X10/4*4+Y10/4*3) -> 30 | AA10: 3 | AB10: 3 | AC10: 3 | AD10: =IF(COUNTA(AA10:AC10)=0,"",AA10/4*4+AB10/4*3+AC10/4*3) -> 7.5 | AE10: 4 | AF10: 4 | AG10: 4 | AH10: =IF(COUNTA(AE10:AG10)=0,"",AE10/4*4+AF10/4*3+AG10/4*3) -> 10 | AI10: 4 | AJ10: 3 | AK10: =IF(COUNTA(AI10:AJ10)=0,"",AI10/4*3+AJ10/4*2) -> 4.5 | AL10: =IF(COUNTA(S10,Z10,AD10,AH10,AK10)<5,"",SUM(S10,Z10,AD10,AH10,AK10)) -> 89.8 | AN10: =IF(AM10="","否","是") -> 否 | AO10: =IF(S10="","",IF(S10>=36,"合格",IF(S10>=31.5,"临界","不合格"))) -> 合格 | AP10: =IF(Z10="","",IF(Z10>=21,"合格",IF(Z10>=18,"临界","不合格"))) -> 合格 | AQ10: =IF(AD10="","",IF(AD10>=7,"合格",IF(AD10>=6,"临界","不合格"))) -> 合格 | AR10: =IF(AH10="","",IF(AH10>=7,"合格",IF(AH10>=6,"临界","不合格"))) -> 合格 | AS10: =IF(AK10="","",IF(AK10>=4,"合格",IF(AK10>=3,"临界","不合格"))) -> 合格 | AT10: =IF(AL10="","",IF(AN10="是","严重失败",IF(AND(S10>=36,Z10>=21,AD10>=7,AH10>=7,AK10>=4,AL10>=80),"生产可用",IF(OR(S10<31.5,Z10<18,AD10<6,AH10<6,AK10<3),"不可用","待复核")))) -> 生产可用 | AW10: 侧脸角度仅清晰显示一只眼，双眼特征不足以完全确认。
A11: R010 | B11: C02 | C11: P02 | D11: Seedream | E11: 5.0 flash | F11: 第二轮 | I11: 3 | J11: 5 | K11: 3 | L11: 3 | M11: 4 | N11: 4 | O11: 3 | P11: 4 | Q11: 3 | R11: 4 | S11: =IF(COUNTA(I11:R11)=0,"",I11/5*4+J11/5*4+K11/5*4+L11/4*8+M11/4*5+N11/4*6+O11/4*4+P11/4*4+Q11/4*4+R11/4*2) -> 37.8 | T11: 4 | U11: 4 | V11: 4 | W11: 4 | X11: 4 | Y11: 4 | Z11: =IF(COUNTA(T11:Y11)=0,"",T11/4*7+U11/4*6+V11/4*6+W11/4*4+X11/4*4+Y11/4*3) -> 30 | AA11: 3 | AB11: 3 | AC11: 3 | AD11: =IF(COUNTA(AA11:AC11)=0,"",AA11/4*4+AB11/4*3+AC11/4*3) -> 7.5 | AE11: 4 | AF11: 4 | AG11: 4 | AH11: =IF(COUNTA(AE11:AG11)=0,"",AE11/4*4+AF11/4*3+AG11/4*3) -> 10 | AI11: 4 | AJ11: 3 | AK11: =IF(COUNTA(AI11:AJ11)=0,"",AI11/4*3+AJ11/4*2) -> 4.5 | AL11: =IF(COUNTA(S11,Z11,AD11,AH11,AK11)<5,"",SUM(S11,Z11,AD11,AH11,AK11)) -> 89.8 | AN11: =IF(AM11="","否","是") -> 否 | AO11: =IF(S11="","",IF(S11>=36,"合格",IF(S11>=31.5,"临界","不合格"))) -> 合格 | AP11: =IF(Z11="","",IF(Z11>=21,"合格",IF(Z11>=18,"临界","不合格"))) -> 合格 | AQ11: =IF(AD11="","",IF(AD11>=7,"合格",IF(AD11>=6,"临界","不合格"))) -> 合格 | AR11: =IF(AH11="","",IF(AH11>=7,"合格",IF(AH11>=6,"临界","不合格"))) -> 合格 | AS11: =IF(AK11="","",IF(AK11>=4,"合格",IF(AK11>=3,"临界","不合格"))) -> 合格 | AT11: =IF(AL11="","",IF(AN11="是","严重失败",IF(AND(S11>=36,Z11>=21,AD11>=7,AH11>=7,AK11>=4,AL11>=80),"生产可用",IF(OR(S11<31.5,Z11<18,AD11<6,AH11<6,AK11<3),"不可用","待复核")))) -> 生产可用 | AW11: 侧脸角度仅清晰显示一只眼，双眼特征不足以完全确认。
A12: R011 | B12: C02 | C12: P02 | D12: GPT image | E12: 2.5 | F12: 第一轮 | I12: 5 | J12: 5 | K12: 4 | L12: 4 | M12: 4 | N12: 4 | O12: 4 | P12: 4 | Q12: 4 | R12: 2 | S12: =IF(COUNTA(I12:R12)=0,"",I12/5*4+J12/5*4+K12/5*4+L12/4*8+M12/4*5+N12/4*6+O12/4*4+P12/4*4+Q12/4*4+R12/4*2) -> 43.2 | T12: 4 | U12: 2 | V12: 4 | W12: 4 | X12: 4 | Y12: 4 | Z12: =IF(COUNTA(T12:Y12)=0,"",T12/4*7+U12/4*6+V12/4*6+W12/4*4+X12/4*4+Y12/4*3) -> 27 | AA12: 0 | AB12: 4 | AC12: 4 | AD12: =IF(COUNTA(AA12:AC12)=0,"",AA12/4*4+AB12/4*3+AC12/4*3) -> 6 | AE12: 4 | AF12: 4 | AG12: 4 | AH12: =IF(COUNTA(AE12:AG12)=0,"",AE12/4*4+AF12/4*3+AG12/4*3) -> 10 | AI12: 4 | AJ12: 3 | AK12: =IF(COUNTA(AI12:AJ12)=0,"",AI12/4*3+AJ12/4*2) -> 4.5 | AL12: =IF(COUNTA(S12,Z12,AD12,AH12,AK12)<5,"",SUM(S12,Z12,AD12,AH12,AK12)) -> 90.7 | AN12: =IF(AM12="","否","是") -> 否 | AO12: =IF(S12="","",IF(S12>=36,"合格",IF(S12>=31.5,"临界","不合格"))) -> 合格 | AP12: =IF(Z12="","",IF(Z12>=21,"合格",IF(Z12>=18,"临界","不合格"))) -> 合格 | AQ12: =IF(AD12="","",IF(AD12>=7,"合格",IF(AD12>=6,"临界","不合格"))) -> 临界 | AR12: =IF(AH12="","",IF(AH12>=7,"合格",IF(AH12>=6,"临界","不合格"))) -> 合格 | AS12: =IF(AK12="","",IF(AK12>=4,"合格",IF(AK12>=3,"临界","不合格"))) -> 合格 | AT12: =IF(AL12="","",IF(AN12="是","严重失败",IF(AND(S12>=36,Z12>=21,AD12>=7,AH12>=7,AK12>=4,AL12>=80),"生产可用",IF(OR(S12<31.5,Z12<18,AD12<6,AH12<6,AK12<3),"不可用","待复核")))) -> 待复核
A13: R012 | B13: C02 | C13: P02 | D13: GPT image | E13: 2.5 | F13: 第二轮 | I13: 5 | J13: 5 | K13: 4 | L13: 4 | M13: 4 | N13: 4 | O13: 4 | P13: 4 | Q13: 4 | R13: 3 | S13: =IF(COUNTA(I13:R13)=0,"",I13/5*4+J13/5*4+K13/5*4+L13/4*8+M13/4*5+N13/4*6+O13/4*4+P13/4*4+Q13/4*4+R13/4*2) -> 43.7 | T13: 4 | U13: 2 | V13: 4 | W13: 4 | X13: 4 | Y13: 4 | Z13: =IF(COUNTA(T13:Y13)=0,"",T13/4*7+U13/4*6+V13/4*6+W13/4*4+X13/4*4+Y13/4*3) -> 27 | AA13: 0 | AB13: 4 | AC13: 4 | AD13: =IF(COUNTA(AA13:AC13)=0,"",AA13/4*4+AB13/4*3+AC13/4*3) -> 6 | AE13: 4 | AF13: 4 | AG13: 4 | AH13: =IF(COUNTA(AE13:AG13)=0,"",AE13/4*4+AF13/4*3+AG13/4*3) -> 10 | AI13: 4 | AJ13: 3 | AK13: =IF(COUNTA(AI13:AJ13)=0,"",AI13/4*3+AJ13/4*2) -> 4.5 | AL13: =IF(COUNTA(S13,Z13,AD13,AH13,AK13)<5,"",SUM(S13,Z13,AD13,AH13,AK13)) -> 91.2 | AN13: =IF(AM13="","否","是") -> 否 | AO13: =IF(S13="","",IF(S13>=36,"合格",IF(S13>=31.5,"临界","不合格"))) -> 合格 | AP13: =IF(Z13="","",IF(Z13>=21,"合格",IF(Z13>=18,"临界","不合格"))) -> 合格 | AQ13: =IF(AD13="","",IF(AD13>=7,"合格",IF(AD13>=6,"临界","不合格"))) -> 临界 | AR13: =IF(AH13="","",IF(AH13>=7,"合格",IF(AH13>=6,"临界","不合格"))) -> 合格 | AS13: =IF(AK13="","",IF(AK13>=4,"合格",IF(AK13>=3,"临界","不合格"))) -> 合格 | AT13: =IF(AL13="","",IF(AN13="是","严重失败",IF(AND(S13>=36,Z13>=21,AD13>=7,AH13>=7,AK13>=4,AL13>=80),"生产可用",IF(OR(S13<31.5,Z13<18,AD13<6,AH13<6,AK13<3),"不可用","待复核")))) -> 待复核
A14: R013 | B14: C03 | C14: P03 | D14: Nano Banana | E14: 3 Lite | F14: 第一轮 | I14: 4 | J14: 5 | K14: 5 | L14: 4 | M14: 4 | N14: 4 | O14: 4 | P14: 4 | Q14: 4 | R14: 4 | S14: =IF(COUNTA(I14:R14)=0,"",I14/5*4+J14/5*4+K14/5*4+L14/4*8+M14/4*5+N14/4*6+O14/4*4+P14/4*4+Q14/4*4+R14/4*2) -> 44.2 | T14: 4 | U14: 4 | V14: 4 | W14: 4 | X14: 4 | Y14: 4 | Z14: =IF(COUNTA(T14:Y14)=0,"",T14/4*7+U14/4*6+V14/4*6+W14/4*4+X14/4*4+Y14/4*3) -> 30 | AA14: 4 | AB14: 4 | AC14: 4 | AD14: =IF(COUNTA(AA14:AC14)=0,"",AA14/4*4+AB14/4*3+AC14/4*3) -> 10 | AE14: 4 | AF14: 4 | AG14: 4 | AH14: =IF(COUNTA(AE14:AG14)=0,"",AE14/4*4+AF14/4*3+AG14/4*3) -> 10 | AI14: 4 | AJ14: 3 | AK14: =IF(COUNTA(AI14:AJ14)=0,"",AI14/4*3+AJ14/4*2) -> 4.5 | AL14: =IF(COUNTA(S14,Z14,AD14,AH14,AK14)<5,"",SUM(S14,Z14,AD14,AH14,AK14)) -> 98.7 | AN14: =IF(AM14="","否","是") -> 否 | AO14: =IF(S14="","",IF(S14>=36,"合格",IF(S14>=31.5,"临界","不合格"))) -> 合格 | AP14: =IF(Z14="","",IF(Z14>=21,"合格",IF(Z14>=18,"临界","不合格"))) -> 合格 | AQ14: =IF(AD14="","",IF(AD14>=7,"合格",IF(AD14>=6,"临界","不合格"))) -> 合格 | AR14: =IF(AH14="","",IF(AH14>=7,"合格",IF(AH14>=6,"临界","不合格"))) -> 合格 | AS14: =IF(AK14="","",IF(AK14>=4,"合格",IF(AK14>=3,"临界","不合格"))) -> 合格 | AT14: =IF(AL14="","",IF(AN14="是","严重失败",IF(AND(S14>=36,Z14>=21,AD14>=7,AH14>=7,AK14>=4,AL14>=80),"生产可用",IF(OR(S14<31.5,Z14<18,AD14<6,AH14<6,AK14<3),"不可用","待复核")))) -> 生产可用
A15: R014 | B15: C03 | C15: P03 | D15: Nano Banana | E15: 3 Lite | F15: 第二轮 | I15: 4 | J15: 5 | K15: 5 | L15: 4 | M15: 4 | N15: 4 | O15: 4 | P15: 4 | Q15: 4 | R15: 4 | S15: =IF(COUNTA(I15:R15)=0,"",I15/5*4+J15/5*4+K15/5*4+L15/4*8+M15/4*5+N15/4*6+O15/4*4+P15/4*4+Q15/4*4+R15/4*2) -> 44.2 | T15: 4 | U15: 4 | V15: 4 | W15: 4 | X15: 4 | Y15: 4 | Z15: =IF(COUNTA(T15:Y15)=0,"",T15/4*7+U15/4*6+V15/4*6+W15/4*4+X15/4*4+Y15/4*3) -> 30 | AA15: 4 | AB15: 4 | AC15: 4 | AD15: =IF(COUNTA(AA15:AC15)=0,"",AA15/4*4+AB15/4*3+AC15/4*3) -> 10 | AE15: 4 | AF15: 4 | AG15: 4 | AH15: =IF(COUNTA(AE15:AG15)=0,"",AE15/4*4+AF15/4*3+AG15/4*3) -> 10 | AI15: 4 | AJ15: 3 | AK15: =IF(COUNTA(AI15:AJ15)=0,"",AI15/4*3+AJ15/4*2) -> 4.5 | AL15: =IF(COUNTA(S15,Z15,AD15,AH15,AK15)<5,"",SUM(S15,Z15,AD15,AH15,AK15)) -> 98.7 | AN15: =IF(AM15="","否","是") -> 否 | AO15: =IF(S15="","",IF(S15>=36,"合格",IF(S15>=31.5,"临界","不合格"))) -> 合格 | AP15: =IF(Z15="","",IF(Z15>=21,"合格",IF(Z15>=18,"临界","不合格"))) -> 合格 | AQ15: =IF(AD15="","",IF(AD15>=7,"合格",IF(AD15>=6,"临界","不合格"))) -> 合格 | AR15: =IF(AH15="","",IF(AH15>=7,"合格",IF(AH15>=6,"临界","不合格"))) -> 合格 | AS15: =IF(AK15="","",IF(AK15>=4,"合格",IF(AK15>=3,"临界","不合格"))) -> 合格 | AT15: =IF(AL15="","",IF(AN15="是","严重失败",IF(AND(S15>=36,Z15>=21,AD15>=7,AH15>=7,AK15>=4,AL15>=80),"生产可用",IF(OR(S15<31.5,Z15<18,AD15<6,AH15<6,AK15<3),"不可用","待复核")))) -> 生产可用
A16: R015 | B16: C03 | C16: P03 | D16: Seedream | E16: 5.0 flash | F16: 第一轮 | I16: 4 | J16: 5 | K16: 5 | L16: 3 | M16: 4 | N16: 3 | O16: 4 | P16: 4 | Q16: 4 | R16: 4 | S16: =IF(COUNTA(I16:R16)=0,"",I16/5*4+J16/5*4+K16/5*4+L16/4*8+M16/4*5+N16/4*6+O16/4*4+P16/4*4+Q16/4*4+R16/4*2) -> 40.7 | T16: 4 | U16: 3 | V16: 4 | W16: 4 | X16: 4 | Y16: 4 | Z16: =IF(COUNTA(T16:Y16)=0,"",T16/4*7+U16/4*6+V16/4*6+W16/4*4+X16/4*4+Y16/4*3) -> 28.5 | AA16: 4 | AB16: 3 | AC16: 3 | AD16: =IF(COUNTA(AA16:AC16)=0,"",AA16/4*4+AB16/4*3+AC16/4*3) -> 8.5 | AE16: 4 | AF16: 4 | AG16: 4 | AH16: =IF(COUNTA(AE16:AG16)=0,"",AE16/4*4+AF16/4*3+AG16/4*3) -> 10 | AI16: 4 | AJ16: 3 | AK16: =IF(COUNTA(AI16:AJ16)=0,"",AI16/4*3+AJ16/4*2) -> 4.5 | AL16: =IF(COUNTA(S16,Z16,AD16,AH16,AK16)<5,"",SUM(S16,Z16,AD16,AH16,AK16)) -> 92.2 | AN16: =IF(AM16="","否","是") -> 否 | AO16: =IF(S16="","",IF(S16>=36,"合格",IF(S16>=31.5,"临界","不合格"))) -> 合格 | AP16: =IF(Z16="","",IF(Z16>=21,"合格",IF(Z16>=18,"临界","不合格"))) -> 合格 | AQ16: =IF(AD16="","",IF(AD16>=7,"合格",IF(AD16>=6,"临界","不合格"))) -> 合格 | AR16: =IF(AH16="","",IF(AH16>=7,"合格",IF(AH16>=6,"临界","不合格"))) -> 合格 | AS16: =IF(AK16="","",IF(AK16>=4,"合格",IF(AK16>=3,"临界","不合格"))) -> 合格 | AT16: =IF(AL16="","",IF(AN16="是","严重失败",IF(AND(S16>=36,Z16>=21,AD16>=7,AH16>=7,AK16>=4,AL16>=80),"生产可用",IF(OR(S16<31.5,Z16<18,AD16<6,AH16<6,AK16<3),"不可用","待复核")))) -> 生产可用
A17: R016 | B17: C03 | C17: P03 | D17: Seedream | E17: 5.0 flash | F17: 第二轮 | I17: 4 | J17: 5 | K17: 5 | L17: 3 | M17: 4 | N17: 3 | O17: 4 | P17: 4 | Q17: 4 | R17: 4 | S17: =IF(COUNTA(I17:R17)=0,"",I17/5*4+J17/5*4+K17/5*4+L17/4*8+M17/4*5+N17/4*6+O17/4*4+P17/4*4+Q17/4*4+R17/4*2) -> 40.7 | T17: 4 | U17: 3 | V17: 4 | W17: 4 | X17: 4 | Y17: 4 | Z17: =IF(COUNTA(T17:Y17)=0,"",T17/4*7+U17/4*6+V17/4*6+W17/4*4+X17/4*4+Y17/4*3) -> 28.5 | AA17: 4 | AB17: 3 | AC17: 3 | AD17: =IF(COUNTA(AA17:AC17)=0,"",AA17/4*4+AB17/4*3+AC17/4*3) -> 8.5 | AE17: 4 | AF17: 4 | AG17: 4 | AH17: =IF(COUNTA(AE17:AG17)=0,"",AE17/4*4+AF17/4*3+AG17/4*3) -> 10 | AI17: 4 | AJ17: 3 | AK17: =IF(COUNTA(AI17:AJ17)=0,"",AI17/4*3+AJ17/4*2) -> 4.5 | AL17: =IF(COUNTA(S17,Z17,AD17,AH17,AK17)<5,"",SUM(S17,Z17,AD17,AH17,AK17)) -> 92.2 | AN17: =IF(AM17="","否","是") -> 否 | AO17: =IF(S17="","",IF(S17>=36,"合格",IF(S17>=31.5,"临界","不合格"))) -> 合格 | AP17: =IF(Z17="","",IF(Z17>=21,"合格",IF(Z17>=18,"临界","不合格"))) -> 合格 | AQ17: =IF(AD17="","",IF(AD17>=7,"合格",IF(AD17>=6,"临界","不合格"))) -> 合格 | AR17: =IF(AH17="","",IF(AH17>=7,"合格",IF(AH17>=6,"临界","不合格"))) -> 合格 | AS17: =IF(AK17="","",IF(AK17>=4,"合格",IF(AK17>=3,"临界","不合格"))) -> 合格 | AT17: =IF(AL17="","",IF(AN17="是","严重失败",IF(AND(S17>=36,Z17>=21,AD17>=7,AH17>=7,AK17>=4,AL17>=80),"生产可用",IF(OR(S17<31.5,Z17<18,AD17<6,AH17<6,AK17<3),"不可用","待复核")))) -> 生产可用
A18: R017 | B18: C03 | C18: P03 | D18: GPT image | E18: 2.5 | F18: 第一轮 | I18: 5 | J18: 5 | K18: 5 | L18: 4 | M18: 4 | N18: 4 | O18: 4 | P18: 4 | Q18: 4 | R18: 4 | S18: =IF(COUNTA(I18:R18)=0,"",I18/5*4+J18/5*4+K18/5*4+L18/4*8+M18/4*5+N18/4*6+O18/4*4+P18/4*4+Q18/4*4+R18/4*2) -> 45 | T18: 4 | U18: 2 | V18: 4 | W18: 3 | X18: 4 | Y18: 4 | Z18: =IF(COUNTA(T18:Y18)=0,"",T18/4*7+U18/4*6+V18/4*6+W18/4*4+X18/4*4+Y18/4*3) -> 26 | AA18: 0 | AB18: 4 | AC18: 4 | AD18: =IF(COUNTA(AA18:AC18)=0,"",AA18/4*4+AB18/4*3+AC18/4*3) -> 6 | AE18: 4 | AF18: 4 | AG18: 4 | AH18: =IF(COUNTA(AE18:AG18)=0,"",AE18/4*4+AF18/4*3+AG18/4*3) -> 10 | AI18: 4 | AJ18: 3 | AK18: =IF(COUNTA(AI18:AJ18)=0,"",AI18/4*3+AJ18/4*2) -> 4.5 | AL18: =IF(COUNTA(S18,Z18,AD18,AH18,AK18)<5,"",SUM(S18,Z18,AD18,AH18,AK18)) -> 91.5 | AN18: =IF(AM18="","否","是") -> 否 | AO18: =IF(S18="","",IF(S18>=36,"合格",IF(S18>=31.5,"临界","不合格"))) -> 合格 | AP18: =IF(Z18="","",IF(Z18>=21,"合格",IF(Z18>=18,"临界","不合格"))) -> 合格 | AQ18: =IF(AD18="","",IF(AD18>=7,"合格",IF(AD18>=6,"临界","不合格"))) -> 临界 | AR18: =IF(AH18="","",IF(AH18>=7,"合格",IF(AH18>=6,"临界","不合格"))) -> 合格 | AS18: =IF(AK18="","",IF(AK18>=4,"合格",IF(AK18>=3,"临界","不合格"))) -> 合格 | AT18: =IF(AL18="","",IF(AN18="是","严重失败",IF(AND(S18>=36,Z18>=21,AD18>=7,AH18>=7,AK18>=4,AL18>=80),"生产可用",IF(OR(S18<31.5,Z18<18,AD18<6,AH18<6,AK18<3),"不可用","待复核")))) -> 待复核
A19: R018 | B19: C03 | C19: P03 | D19: GPT image | E19: 2.5 | F19: 第二轮 | I19: 5 | J19: 5 | K19: 5 | L19: 4 | M19: 4 | N19: 4 | O19: 4 | P19: 4 | Q19: 4 | R19: 4 | S19: =IF(COUNTA(I19:R19)=0,"",I19/5*4+J19/5*4+K19/5*4+L19/4*8+M19/4*5+N19/4*6+O19/4*4+P19/4*4+Q19/4*4+R19/4*2) -> 45 | T19: 4 | U19: 2 | V19: 4 | W19: 3 | X19: 4 | Y19: 4 | Z19: =IF(COUNTA(T19:Y19)=0,"",T19/4*7+U19/4*6+V19/4*6+W19/4*4+X19/4*4+Y19/4*3) -> 26 | AA19: 0 | AB19: 4 | AC19: 4 | AD19: =IF(COUNTA(AA19:AC19)=0,"",AA19/4*4+AB19/4*3+AC19/4*3) -> 6 | AE19: 4 | AF19: 4 | AG19: 4 | AH19: =IF(COUNTA(AE19:AG19)=0,"",AE19/4*4+AF19/4*3+AG19/4*3) -> 10 | AI19: 4 | AJ19: 3 | AK19: =IF(COUNTA(AI19:AJ19)=0,"",AI19/4*3+AJ19/4*2) -> 4.5 | AL19: =IF(COUNTA(S19,Z19,AD19,AH19,AK19)<5,"",SUM(S19,Z19,AD19,AH19,AK19)) -> 91.5 | AN19: =IF(AM19="","否","是") -> 否 | AO19: =IF(S19="","",IF(S19>=36,"合格",IF(S19>=31.5,"临界","不合格"))) -> 合格 | AP19: =IF(Z19="","",IF(Z19>=21,"合格",IF(Z19>=18,"临界","不合格"))) -> 合格 | AQ19: =IF(AD19="","",IF(AD19>=7,"合格",IF(AD19>=6,"临界","不合格"))) -> 临界 | AR19: =IF(AH19="","",IF(AH19>=7,"合格",IF(AH19>=6,"临界","不合格"))) -> 合格 | AS19: =IF(AK19="","",IF(AK19>=4,"合格",IF(AK19>=3,"临界","不合格"))) -> 合格 | AT19: =IF(AL19="","",IF(AN19="是","严重失败",IF(AND(S19>=36,Z19>=21,AD19>=7,AH19>=7,AK19>=4,AL19>=80),"生产可用",IF(OR(S19<31.5,Z19<18,AD19<6,AH19<6,AK19<3),"不可用","待复核")))) -> 待复核
A20: R019 | B20: C04 | C20: P04 | D20: Nano Banana | E20: 3 Lite | F20: 第一轮 | I20: 5 | J20: 5 | K20: 4 | L20: 4 | M20: 4 | N20: 4 | O20: 4 | P20: 4 | Q20: 4 | R20: 4 | S20: =IF(COUNTA(I20:R20)=0,"",I20/5*4+J20/5*4+K20/5*4+L20/4*8+M20/4*5+N20/4*6+O20/4*4+P20/4*4+Q20/4*4+R20/4*2) -> 44.2 | T20: 4 | U20: 4 | V20: 4 | W20: 4 | X20: 4 | Y20: 4 | Z20: =IF(COUNTA(T20:Y20)=0,"",T20/4*7+U20/4*6+V20/4*6+W20/4*4+X20/4*4+Y20/4*3) -> 30 | AA20: 4 | AB20: 4 | AC20: 4 | AD20: =IF(COUNTA(AA20:AC20)=0,"",AA20/4*4+AB20/4*3+AC20/4*3) -> 10 | AE20: 4 | AF20: 4 | AG20: 4 | AH20: =IF(COUNTA(AE20:AG20)=0,"",AE20/4*4+AF20/4*3+AG20/4*3) -> 10 | AI20: 4 | AJ20: 3 | AK20: =IF(COUNTA(AI20:AJ20)=0,"",AI20/4*3+AJ20/4*2) -> 4.5 | AL20: =IF(COUNTA(S20,Z20,AD20,AH20,AK20)<5,"",SUM(S20,Z20,AD20,AH20,AK20)) -> 98.7 | AN20: =IF(AM20="","否","是") -> 否 | AO20: =IF(S20="","",IF(S20>=36,"合格",IF(S20>=31.5,"临界","不合格"))) -> 合格 | AP20: =IF(Z20="","",IF(Z20>=21,"合格",IF(Z20>=18,"临界","不合格"))) -> 合格 | AQ20: =IF(AD20="","",IF(AD20>=7,"合格",IF(AD20>=6,"临界","不合格"))) -> 合格 | AR20: =IF(AH20="","",IF(AH20>=7,"合格",IF(AH20>=6,"临界","不合格"))) -> 合格 | AS20: =IF(AK20="","",IF(AK20>=4,"合格",IF(AK20>=3,"临界","不合格"))) -> 合格 | AT20: =IF(AL20="","",IF(AN20="是","严重失败",IF(AND(S20>=36,Z20>=21,AD20>=7,AH20>=7,AK20>=4,AL20>=80),"生产可用",IF(OR(S20<31.5,Z20<18,AD20<6,AH20<6,AK20<3),"不可用","待复核")))) -> 生产可用
A21: R020 | B21: C04 | C21: P04 | D21: Nano Banana | E21: 3 Lite | F21: 第二轮 | I21: 5 | J21: 5 | K21: 4 | L21: 4 | M21: 4 | N21: 4 | O21: 4 | P21: 4 | Q21: 4 | R21: 4 | S21: =IF(COUNTA(I21:R21)=0,"",I21/5*4+J21/5*4+K21/5*4+L21/4*8+M21/4*5+N21/4*6+O21/4*4+P21/4*4+Q21/4*4+R21/4*2) -> 44.2 | T21: 4 | U21: 4 | V21: 4 | W21: 4 | X21: 4 | Y21: 4 | Z21: =IF(COUNTA(T21:Y21)=0,"",T21/4*7+U21/4*6+V21/4*6+W21/4*4+X21/4*4+Y21/4*3) -> 30 | AA21: 4 | AB21: 4 | AC21: 4 | AD21: =IF(COUNTA(AA21:AC21)=0,"",AA21/4*4+AB21/4*3+AC21/4*3) -> 10 | AE21: 4 | AF21: 4 | AG21: 4 | AH21: =IF(COUNTA(AE21:AG21)=0,"",AE21/4*4+AF21/4*3+AG21/4*3) -> 10 | AI21: 4 | AJ21: 3 | AK21: =IF(COUNTA(AI21:AJ21)=0,"",AI21/4*3+AJ21/4*2) -> 4.5 | AL21: =IF(COUNTA(S21,Z21,AD21,AH21,AK21)<5,"",SUM(S21,Z21,AD21,AH21,AK21)) -> 98.7 | AN21: =IF(AM21="","否","是") -> 否 | AO21: =IF(S21="","",IF(S21>=36,"合格",IF(S21>=31.5,"临界","不合格"))) -> 合格 | AP21: =IF(Z21="","",IF(Z21>=21,"合格",IF(Z21>=18,"临界","不合格"))) -> 合格 | AQ21: =IF(AD21="","",IF(AD21>=7,"合格",IF(AD21>=6,"临界","不合格"))) -> 合格 | AR21: =IF(AH21="","",IF(AH21>=7,"合格",IF(AH21>=6,"临界","不合格"))) -> 合格 | AS21: =IF(AK21="","",IF(AK21>=4,"合格",IF(AK21>=3,"临界","不合格"))) -> 合格 | AT21: =IF(AL21="","",IF(AN21="是","严重失败",IF(AND(S21>=36,Z21>=21,AD21>=7,AH21>=7,AK21>=4,AL21>=80),"生产可用",IF(OR(S21<31.5,Z21<18,AD21<6,AH21<6,AK21<3),"不可用","待复核")))) -> 生产可用
A22: R021 | B22: C04 | C22: P04 | D22: Seedream | E22: 5.0 flash | F22: 第一轮 | I22: 3 | J22: 3 | K22: 2 | L22: 2 | M22: 4 | N22: 4 | O22: 2 | P22: 2 | Q22: 3 | R22: 2 | S22: =IF(COUNTA(I22:R22)=0,"",I22/5*4+J22/5*4+K22/5*4+L22/4*8+M22/4*5+N22/4*6+O22/4*4+P22/4*4+Q22/4*4+R22/4*2) -> 29.4 | T22: 4 | U22: 4 | V22: 4 | W22: 4 | X22: 4 | Y22: 4 | Z22: =IF(COUNTA(T22:Y22)=0,"",T22/4*7+U22/4*6+V22/4*6+W22/4*4+X22/4*4+Y22/4*3) -> 30 | AA22: 3 | AB22: 2 | AC22: 3 | AD22: =IF(COUNTA(AA22:AC22)=0,"",AA22/4*4+AB22/4*3+AC22/4*3) -> 6.75 | AE22: 4 | AF22: 4 | AG22: 4 | AH22: =IF(COUNTA(AE22:AG22)=0,"",AE22/4*4+AF22/4*3+AG22/4*3) -> 10 | AI22: 4 | AJ22: 3 | AK22: =IF(COUNTA(AI22:AJ22)=0,"",AI22/4*3+AJ22/4*2) -> 4.5 | AL22: =IF(COUNTA(S22,Z22,AD22,AH22,AK22)<5,"",SUM(S22,Z22,AD22,AH22,AK22)) -> 80.65 | AN22: =IF(AM22="","否","是") -> 否 | AO22: =IF(S22="","",IF(S22>=36,"合格",IF(S22>=31.5,"临界","不合格"))) -> 不合格 | AP22: =IF(Z22="","",IF(Z22>=21,"合格",IF(Z22>=18,"临界","不合格"))) -> 合格 | AQ22: =IF(AD22="","",IF(AD22>=7,"合格",IF(AD22>=6,"临界","不合格"))) -> 临界 | AR22: =IF(AH22="","",IF(AH22>=7,"合格",IF(AH22>=6,"临界","不合格"))) -> 合格 | AS22: =IF(AK22="","",IF(AK22>=4,"合格",IF(AK22>=3,"临界","不合格"))) -> 合格 | AT22: =IF(AL22="","",IF(AN22="是","严重失败",IF(AND(S22>=36,Z22>=21,AD22>=7,AH22>=7,AK22>=4,AL22>=80),"生产可用",IF(OR(S22<31.5,Z22<18,AD22<6,AH22<6,AK22<3),"不可用","待复核")))) -> 不可用
A23: R022 | B23: C04 | C23: P04 | D23: Seedream | E23: 5.0 flash | F23: 第二轮 | I23: 3 | J23: 3 | K23: 2 | L23: 3 | M23: 4 | N23: 4 | O23: 2 | P23: 2 | Q23: 3 | R23: 3 | S23: =IF(COUNTA(I23:R23)=0,"",I23/5*4+J23/5*4+K23/5*4+L23/4*8+M23/4*5+N23/4*6+O23/4*4+P23/4*4+Q23/4*4+R23/4*2) -> 31.9 | T23: 4 | U23: 4 | V23: 4 | W23: 4 | X23: 4 | Y23: 4 | Z23: =IF(COUNTA(T23:Y23)=0,"",T23/4*7+U23/4*6+V23/4*6+W23/4*4+X23/4*4+Y23/4*3) -> 30 | AA23: 3 | AB23: 2 | AC23: 3 | AD23: =IF(COUNTA(AA23:AC23)=0,"",AA23/4*4+AB23/4*3+AC23/4*3) -> 6.75 | AE23: 4 | AF23: 4 | AG23: 4 | AH23: =IF(COUNTA(AE23:AG23)=0,"",AE23/4*4+AF23/4*3+AG23/4*3) -> 10 | AI23: 4 | AJ23: 3 | AK23: =IF(COUNTA(AI23:AJ23)=0,"",AI23/4*3+AJ23/4*2) -> 4.5 | AL23: =IF(COUNTA(S23,Z23,AD23,AH23,AK23)<5,"",SUM(S23,Z23,AD23,AH23,AK23)) -> 83.15 | AN23: =IF(AM23="","否","是") -> 否 | AO23: =IF(S23="","",IF(S23>=36,"合格",IF(S23>=31.5,"临界","不合格"))) -> 临界 | AP23: =IF(Z23="","",IF(Z23>=21,"合格",IF(Z23>=18,"临界","不合格"))) -> 合格 | AQ23: =IF(AD23="","",IF(AD23>=7,"合格",IF(AD23>=6,"临界","不合格"))) -> 临界 | AR23: =IF(AH23="","",IF(AH23>=7,"合格",IF(AH23>=6,"临界","不合格"))) -> 合格 | AS23: =IF(AK23="","",IF(AK23>=4,"合格",IF(AK23>=3,"临界","不合格"))) -> 合格 | AT23: =IF(AL23="","",IF(AN23="是","严重失败",IF(AND(S23>=36,Z23>=21,AD23>=7,AH23>=7,AK23>=4,AL23>=80),"生产可用",IF(OR(S23<31.5,Z23<18,AD23<6,AH23<6,AK23<3),"不可用","待复核")))) -> 待复核
A24: R023 | B24: C04 | C24: P04 | D24: GPT image | E24: 2.5 | F24: 第一轮 | I24: 5 | J24: 4 | K24: 4 | L24: 4 | M24: 4 | N24: 4 | O24: 3 | P24: 4 | Q24: 4 | R24: 4 | S24: =IF(COUNTA(I24:R24)=0,"",I24/5*4+J24/5*4+K24/5*4+L24/4*8+M24/4*5+N24/4*6+O24/4*4+P24/4*4+Q24/4*4+R24/4*2) -> 42.4 | T24: 4 | U24: 4 | V24: 4 | W24: 4 | X24: 4 | Y24: 3 | Z24: =IF(COUNTA(T24:Y24)=0,"",T24/4*7+U24/4*6+V24/4*6+W24/4*4+X24/4*4+Y24/4*3) -> 29.25 | AA24: 0 | AB24: 4 | AC24: 4 | AD24: =IF(COUNTA(AA24:AC24)=0,"",AA24/4*4+AB24/4*3+AC24/4*3) -> 6 | AE24: 4 | AF24: 4 | AG24: 4 | AH24: =IF(COUNTA(AE24:AG24)=0,"",AE24/4*4+AF24/4*3+AG24/4*3) -> 10 | AI24: 4 | AJ24: 3 | AK24: =IF(COUNTA(AI24:AJ24)=0,"",AI24/4*3+AJ24/4*2) -> 4.5 | AL24: =IF(COUNTA(S24,Z24,AD24,AH24,AK24)<5,"",SUM(S24,Z24,AD24,AH24,AK24)) -> 92.15 | AN24: =IF(AM24="","否","是") -> 否 | AO24: =IF(S24="","",IF(S24>=36,"合格",IF(S24>=31.5,"临界","不合格"))) -> 合格 | AP24: =IF(Z24="","",IF(Z24>=21,"合格",IF(Z24>=18,"临界","不合格"))) -> 合格 | AQ24: =IF(AD24="","",IF(AD24>=7,"合格",IF(AD24>=6,"临界","不合格"))) -> 临界 | AR24: =IF(AH24="","",IF(AH24>=7,"合格",IF(AH24>=6,"临界","不合格"))) -> 合格 | AS24: =IF(AK24="","",IF(AK24>=4,"合格",IF(AK24>=3,"临界","不合格"))) -> 合格 | AT24: =IF(AL24="","",IF(AN24="是","严重失败",IF(AND(S24>=36,Z24>=21,AD24>=7,AH24>=7,AK24>=4,AL24>=80),"生产可用",IF(OR(S24<31.5,Z24<18,AD24<6,AH24<6,AK24<3),"不可用","待复核")))) -> 待复核
A25: R024 | B25: C04 | C25: P04 | D25: GPT image | E25: 2.5 | F25: 第二轮 | I25: 5 | J25: 4 | K25: 4 | L25: 4 | M25: 4 | N25: 4 | O25: 3 | P25: 4 | Q25: 4 | R25: 4 | S25: =IF(COUNTA(I25:R25)=0,"",I25/5*4+J25/5*4+K25/5*4+L25/4*8+M25/4*5+N25/4*6+O25/4*4+P25/4*4+Q25/4*4+R25/4*2) -> 42.4 | T25: 4 | U25: 4 | V25: 4 | W25: 4 | X25: 4 | Y25: 4 | Z25: =IF(COUNTA(T25:Y25)=0,"",T25/4*7+U25/4*6+V25/4*6+W25/4*4+X25/4*4+Y25/4*3) -> 30 | AA25: 0 | AB25: 4 | AC25: 4 | AD25: =IF(COUNTA(AA25:AC25)=0,"",AA25/4*4+AB25/4*3+AC25/4*3) -> 6 | AE25: 4 | AF25: 4 | AG25: 4 | AH25: =IF(COUNTA(AE25:AG25)=0,"",AE25/4*4+AF25/4*3+AG25/4*3) -> 10 | AI25: 4 | AJ25: 3 | AK25: =IF(COUNTA(AI25:AJ25)=0,"",AI25/4*3+AJ25/4*2) -> 4.5 | AL25: =IF(COUNTA(S25,Z25,AD25,AH25,AK25)<5,"",SUM(S25,Z25,AD25,AH25,AK25)) -> 92.9 | AN25: =IF(AM25="","否","是") -> 否 | AO25: =IF(S25="","",IF(S25>=36,"合格",IF(S25>=31.5,"临界","不合格"))) -> 合格 | AP25: =IF(Z25="","",IF(Z25>=21,"合格",IF(Z25>=18,"临界","不合格"))) -> 合格 | AQ25: =IF(AD25="","",IF(AD25>=7,"合格",IF(AD25>=6,"临界","不合格"))) -> 临界 | AR25: =IF(AH25="","",IF(AH25>=7,"合格",IF(AH25>=6,"临界","不合格"))) -> 合格 | AS25: =IF(AK25="","",IF(AK25>=4,"合格",IF(AK25>=3,"临界","不合格"))) -> 合格 | AT25: =IF(AL25="","",IF(AN25="是","严重失败",IF(AND(S25>=36,Z25>=21,AD25>=7,AH25>=7,AK25>=4,AL25>=80),"生产可用",IF(OR(S25<31.5,Z25<18,AD25<6,AH25<6,AK25<3),"不可用","待复核")))) -> 待复核
A26: R025 | B26: C05 | C26: P05 | D26: Nano Banana | E26: 3 Lite | F26: 第一轮 | I26: 5 | J26: 5 | K26: 5 | L26: 4 | M26: 4 | N26: 4 | O26: 4 | P26: 4 | Q26: 4 | R26: 4 | S26: =IF(COUNTA(I26:R26)=0,"",I26/5*4+J26/5*4+K26/5*4+L26/4*8+M26/4*5+N26/4*6+O26/4*4+P26/4*4+Q26/4*4+R26/4*2) -> 45 | T26: 4 | U26: 2 | V26: 4 | W26: 3 | X26: 4 | Y26: 4 | Z26: =IF(COUNTA(T26:Y26)=0,"",T26/4*7+U26/4*6+V26/4*6+W26/4*4+X26/4*4+Y26/4*3) -> 26 | AA26: 4 | AB26: 4 | AC26: 4 | AD26: =IF(COUNTA(AA26:AC26)=0,"",AA26/4*4+AB26/4*3+AC26/4*3) -> 10 | AE26: 4 | AF26: 4 | AG26: 4 | AH26: =IF(COUNTA(AE26:AG26)=0,"",AE26/4*4+AF26/4*3+AG26/4*3) -> 10 | AI26: 4 | AJ26: 3 | AK26: =IF(COUNTA(AI26:AJ26)=0,"",AI26/4*3+AJ26/4*2) -> 4.5 | AL26: =IF(COUNTA(S26,Z26,AD26,AH26,AK26)<5,"",SUM(S26,Z26,AD26,AH26,AK26)) -> 95.5 | AN26: =IF(AM26="","否","是") -> 否 | AO26: =IF(S26="","",IF(S26>=36,"合格",IF(S26>=31.5,"临界","不合格"))) -> 合格 | AP26: =IF(Z26="","",IF(Z26>=21,"合格",IF(Z26>=18,"临界","不合格"))) -> 合格 | AQ26: =IF(AD26="","",IF(AD26>=7,"合格",IF(AD26>=6,"临界","不合格"))) -> 合格 | AR26: =IF(AH26="","",IF(AH26>=7,"合格",IF(AH26>=6,"临界","不合格"))) -> 合格 | AS26: =IF(AK26="","",IF(AK26>=4,"合格",IF(AK26>=3,"临界","不合格"))) -> 合格 | AT26: =IF(AL26="","",IF(AN26="是","严重失败",IF(AND(S26>=36,Z26>=21,AD26>=7,AH26>=7,AK26>=4,AL26>=80),"生产可用",IF(OR(S26<31.5,Z26<18,AD26<6,AH26<6,AK26<3),"不可用","待复核")))) -> 生产可用
A27: R026 | B27: C05 | C27: P05 | D27: Nano Banana | E27: 3 Lite | F27: 第二轮 | I27: 5 | J27: 5 | K27: 5 | L27: 4 | M27: 4 | N27: 4 | O27: 4 | P27: 4 | Q27: 4 | R27: 4 | S27: =IF(COUNTA(I27:R27)=0,"",I27/5*4+J27/5*4+K27/5*4+L27/4*8+M27/4*5+N27/4*6+O27/4*4+P27/4*4+Q27/4*4+R27/4*2) -> 45 | T27: 4 | U27: 4 | V27: 4 | W27: 4 | X27: 4 | Y27: 4 | Z27: =IF(COUNTA(T27:Y27)=0,"",T27/4*7+U27/4*6+V27/4*6+W27/4*4+X27/4*4+Y27/4*3) -> 30 | AA27: 4 | AB27: 4 | AC27: 4 | AD27: =IF(COUNTA(AA27:AC27)=0,"",AA27/4*4+AB27/4*3+AC27/4*3) -> 10 | AE27: 4 | AF27: 4 | AG27: 4 | AH27: =IF(COUNTA(AE27:AG27)=0,"",AE27/4*4+AF27/4*3+AG27/4*3) -> 10 | AI27: 4 | AJ27: 3 | AK27: =IF(COUNTA(AI27:AJ27)=0,"",AI27/4*3+AJ27/4*2) -> 4.5 | AL27: =IF(COUNTA(S27,Z27,AD27,AH27,AK27)<5,"",SUM(S27,Z27,AD27,AH27,AK27)) -> 99.5 | AN27: =IF(AM27="","否","是") -> 否 | AO27: =IF(S27="","",IF(S27>=36,"合格",IF(S27>=31.5,"临界","不合格"))) -> 合格 | AP27: =IF(Z27="","",IF(Z27>=21,"合格",IF(Z27>=18,"临界","不合格"))) -> 合格 | AQ27: =IF(AD27="","",IF(AD27>=7,"合格",IF(AD27>=6,"临界","不合格"))) -> 合格 | AR27: =IF(AH27="","",IF(AH27>=7,"合格",IF(AH27>=6,"临界","不合格"))) -> 合格 | AS27: =IF(AK27="","",IF(AK27>=4,"合格",IF(AK27>=3,"临界","不合格"))) -> 合格 | AT27: =IF(AL27="","",IF(AN27="是","严重失败",IF(AND(S27>=36,Z27>=21,AD27>=7,AH27>=7,AK27>=4,AL27>=80),"生产可用",IF(OR(S27<31.5,Z27<18,AD27<6,AH27<6,AK27<3),"不可用","待复核")))) -> 生产可用
A28: R027 | B28: C05 | C28: P05 | D28: Seedream | E28: 5.0 flash | F28: 第一轮 | I28: 4 | J28: 4 | K28: 4 | L28: 3 | M28: 4 | N28: 3 | O28: 4 | P28: 4 | Q28: 4 | R28: 3 | S28: =IF(COUNTA(I28:R28)=0,"",I28/5*4+J28/5*4+K28/5*4+L28/4*8+M28/4*5+N28/4*6+O28/4*4+P28/4*4+Q28/4*4+R28/4*2) -> 38.6 | T28: 4 | U28: 4 | V28: 4 | W28: 4 | X28: 4 | Y28: 4 | Z28: =IF(COUNTA(T28:Y28)=0,"",T28/4*7+U28/4*6+V28/4*6+W28/4*4+X28/4*4+Y28/4*3) -> 30 | AA28: 4 | AB28: 3 | AC28: 3 | AD28: =IF(COUNTA(AA28:AC28)=0,"",AA28/4*4+AB28/4*3+AC28/4*3) -> 8.5 | AE28: 4 | AF28: 4 | AG28: 4 | AH28: =IF(COUNTA(AE28:AG28)=0,"",AE28/4*4+AF28/4*3+AG28/4*3) -> 10 | AI28: 4 | AJ28: 3 | AK28: =IF(COUNTA(AI28:AJ28)=0,"",AI28/4*3+AJ28/4*2) -> 4.5 | AL28: =IF(COUNTA(S28,Z28,AD28,AH28,AK28)<5,"",SUM(S28,Z28,AD28,AH28,AK28)) -> 91.6 | AN28: =IF(AM28="","否","是") -> 否 | AO28: =IF(S28="","",IF(S28>=36,"合格",IF(S28>=31.5,"临界","不合格"))) -> 合格 | AP28: =IF(Z28="","",IF(Z28>=21,"合格",IF(Z28>=18,"临界","不合格"))) -> 合格 | AQ28: =IF(AD28="","",IF(AD28>=7,"合格",IF(AD28>=6,"临界","不合格"))) -> 合格 | AR28: =IF(AH28="","",IF(AH28>=7,"合格",IF(AH28>=6,"临界","不合格"))) -> 合格 | AS28: =IF(AK28="","",IF(AK28>=4,"合格",IF(AK28>=3,"临界","不合格"))) -> 合格 | AT28: =IF(AL28="","",IF(AN28="是","严重失败",IF(AND(S28>=36,Z28>=21,AD28>=7,AH28>=7,AK28>=4,AL28>=80),"生产可用",IF(OR(S28<31.5,Z28<18,AD28<6,AH28<6,AK28<3),"不可用","待复核")))) -> 生产可用
A29: R028 | B29: C05 | C29: P05 | D29: Seedream | E29: 5.0 flash | F29: 第二轮 | I29: 4 | J29: 4 | K29: 4 | L29: 3 | M29: 4 | N29: 3 | O29: 4 | P29: 4 | Q29: 4 | R29: 3 | S29: =IF(COUNTA(I29:R29)=0,"",I29/5*4+J29/5*4+K29/5*4+L29/4*8+M29/4*5+N29/4*6+O29/4*4+P29/4*4+Q29/4*4+R29/4*2) -> 38.6 | T29: 4 | U29: 4 | V29: 4 | W29: 4 | X29: 4 | Y29: 4 | Z29: =IF(COUNTA(T29:Y29)=0,"",T29/4*7+U29/4*6+V29/4*6+W29/4*4+X29/4*4+Y29/4*3) -> 30 | AA29: 4 | AB29: 3 | AC29: 3 | AD29: =IF(COUNTA(AA29:AC29)=0,"",AA29/4*4+AB29/4*3+AC29/4*3) -> 8.5 | AE29: 4 | AF29: 4 | AG29: 4 | AH29: =IF(COUNTA(AE29:AG29)=0,"",AE29/4*4+AF29/4*3+AG29/4*3) -> 10 | AI29: 4 | AJ29: 3 | AK29: =IF(COUNTA(AI29:AJ29)=0,"",AI29/4*3+AJ29/4*2) -> 4.5 | AL29: =IF(COUNTA(S29,Z29,AD29,AH29,AK29)<5,"",SUM(S29,Z29,AD29,AH29,AK29)) -> 91.6 | AN29: =IF(AM29="","否","是") -> 否 | AO29: =IF(S29="","",IF(S29>=36,"合格",IF(S29>=31.5,"临界","不合格"))) -> 合格 | AP29: =IF(Z29="","",IF(Z29>=21,"合格",IF(Z29>=18,"临界","不合格"))) -> 合格 | AQ29: =IF(AD29="","",IF(AD29>=7,"合格",IF(AD29>=6,"临界","不合格"))) -> 合格 | AR29: =IF(AH29="","",IF(AH29>=7,"合格",IF(AH29>=6,"临界","不合格"))) -> 合格 | AS29: =IF(AK29="","",IF(AK29>=4,"合格",IF(AK29>=3,"临界","不合格"))) -> 合格 | AT29: =IF(AL29="","",IF(AN29="是","严重失败",IF(AND(S29>=36,Z29>=21,AD29>=7,AH29>=7,AK29>=4,AL29>=80),"生产可用",IF(OR(S29<31.5,Z29<18,AD29<6,AH29<6,AK29<3),"不可用","待复核")))) -> 生产可用
A30: R029 | B30: C05 | C30: P05 | D30: GPT image | E30: 2.5 | F30: 第一轮 | I30: 3 | J30: 5 | K30: 4 | L30: 4 | M30: 4 | N30: 3 | O30: 4 | P30: 4 | Q30: 4 | R30: 4 | S30: =IF(COUNTA(I30:R30)=0,"",I30/5*4+J30/5*4+K30/5*4+L30/4*8+M30/4*5+N30/4*6+O30/4*4+P30/4*4+Q30/4*4+R30/4*2) -> 41.1 | T30: 4 | U30: 4 | V30: 4 | W30: 3 | X30: 4 | Y30: 3 | Z30: =IF(COUNTA(T30:Y30)=0,"",T30/4*7+U30/4*6+V30/4*6+W30/4*4+X30/4*4+Y30/4*3) -> 28.25 | AA30: 0 | AB30: 4 | AC30: 4 | AD30: =IF(COUNTA(AA30:AC30)=0,"",AA30/4*4+AB30/4*3+AC30/4*3) -> 6 | AE30: 4 | AF30: 4 | AG30: 4 | AH30: =IF(COUNTA(AE30:AG30)=0,"",AE30/4*4+AF30/4*3+AG30/4*3) -> 10 | AI30: 4 | AJ30: 3 | AK30: =IF(COUNTA(AI30:AJ30)=0,"",AI30/4*3+AJ30/4*2) -> 4.5 | AL30: =IF(COUNTA(S30,Z30,AD30,AH30,AK30)<5,"",SUM(S30,Z30,AD30,AH30,AK30)) -> 89.85 | AN30: =IF(AM30="","否","是") -> 否 | AO30: =IF(S30="","",IF(S30>=36,"合格",IF(S30>=31.5,"临界","不合格"))) -> 合格 | AP30: =IF(Z30="","",IF(Z30>=21,"合格",IF(Z30>=18,"临界","不合格"))) -> 合格 | AQ30: =IF(AD30="","",IF(AD30>=7,"合格",IF(AD30>=6,"临界","不合格"))) -> 临界 | AR30: =IF(AH30="","",IF(AH30>=7,"合格",IF(AH30>=6,"临界","不合格"))) -> 合格 | AS30: =IF(AK30="","",IF(AK30>=4,"合格",IF(AK30>=3,"临界","不合格"))) -> 合格 | AT30: =IF(AL30="","",IF(AN30="是","严重失败",IF(AND(S30>=36,Z30>=21,AD30>=7,AH30>=7,AK30>=4,AL30>=80),"生产可用",IF(OR(S30<31.5,Z30<18,AD30<6,AH30<6,AK30<3),"不可用","待复核")))) -> 待复核
A31: R030 | B31: C05 | C31: P05 | D31: GPT image | E31: 2.5 | F31: 第二轮 | I31: 3 | J31: 5 | K31: 4 | L31: 4 | M31: 4 | N31: 3 | O31: 4 | P31: 4 | Q31: 4 | R31: 4 | S31: =IF(COUNTA(I31:R31)=0,"",I31/5*4+J31/5*4+K31/5*4+L31/4*8+M31/4*5+N31/4*6+O31/4*4+P31/4*4+Q31/4*4+R31/4*2) -> 41.1 | T31: 4 | U31: 4 | V31: 4 | W31: 4 | X31: 4 | Y31: 4 | Z31: =IF(COUNTA(T31:Y31)=0,"",T31/4*7+U31/4*6+V31/4*6+W31/4*4+X31/4*4+Y31/4*3) -> 30 | AA31: 0 | AB31: 4 | AC31: 4 | AD31: =IF(COUNTA(AA31:AC31)=0,"",AA31/4*4+AB31/4*3+AC31/4*3) -> 6 | AE31: 4 | AF31: 4 | AG31: 4 | AH31: =IF(COUNTA(AE31:AG31)=0,"",AE31/4*4+AF31/4*3+AG31/4*3) -> 10 | AI31: 4 | AJ31: 3 | AK31: =IF(COUNTA(AI31:AJ31)=0,"",AI31/4*3+AJ31/4*2) -> 4.5 | AL31: =IF(COUNTA(S31,Z31,AD31,AH31,AK31)<5,"",SUM(S31,Z31,AD31,AH31,AK31)) -> 91.6 | AN31: =IF(AM31="","否","是") -> 否 | AO31: =IF(S31="","",IF(S31>=36,"合格",IF(S31>=31.5,"临界","不合格"))) -> 合格 | AP31: =IF(Z31="","",IF(Z31>=21,"合格",IF(Z31>=18,"临界","不合格"))) -> 合格 | AQ31: =IF(AD31="","",IF(AD31>=7,"合格",IF(AD31>=6,"临界","不合格"))) -> 临界 | AR31: =IF(AH31="","",IF(AH31>=7,"合格",IF(AH31>=6,"临界","不合格"))) -> 合格 | AS31: =IF(AK31="","",IF(AK31>=4,"合格",IF(AK31>=3,"临界","不合格"))) -> 合格 | AT31: =IF(AL31="","",IF(AN31="是","严重失败",IF(AND(S31>=36,Z31>=21,AD31>=7,AH31>=7,AK31>=4,AL31>=80),"生产可用",IF(OR(S31<31.5,Z31<18,AD31<6,AH31<6,AK31<3),"不可用","待复核")))) -> 待复核
A32: R031 | B32: C06 | C32: P06 | D32: Nano Banana | E32: 3 Lite | F32: 第一轮 | I32: 5 | J32: 5 | K32: 5 | L32: 4 | M32: 4 | N32: 4 | O32: 4 | P32: 4 | Q32: 4 | R32: 4 | S32: =IF(COUNTA(I32:R32)=0,"",I32/5*4+J32/5*4+K32/5*4+L32/4*8+M32/4*5+N32/4*6+O32/4*4+P32/4*4+Q32/4*4+R32/4*2) -> 45 | T32: 4 | U32: 4 | V32: 4 | W32: 4 | X32: 4 | Y32: 4 | Z32: =IF(COUNTA(T32:Y32)=0,"",T32/4*7+U32/4*6+V32/4*6+W32/4*4+X32/4*4+Y32/4*3) -> 30 | AA32: 4 | AB32: 4 | AC32: 4 | AD32: =IF(COUNTA(AA32:AC32)=0,"",AA32/4*4+AB32/4*3+AC32/4*3) -> 10 | AE32: 4 | AF32: 4 | AG32: 4 | AH32: =IF(COUNTA(AE32:AG32)=0,"",AE32/4*4+AF32/4*3+AG32/4*3) -> 10 | AI32: 4 | AJ32: 3 | AK32: =IF(COUNTA(AI32:AJ32)=0,"",AI32/4*3+AJ32/4*2) -> 4.5 | AL32: =IF(COUNTA(S32,Z32,AD32,AH32,AK32)<5,"",SUM(S32,Z32,AD32,AH32,AK32)) -> 99.5 | AN32: =IF(AM32="","否","是") -> 否 | AO32: =IF(S32="","",IF(S32>=36,"合格",IF(S32>=31.5,"临界","不合格"))) -> 合格 | AP32: =IF(Z32="","",IF(Z32>=21,"合格",IF(Z32>=18,"临界","不合格"))) -> 合格 | AQ32: =IF(AD32="","",IF(AD32>=7,"合格",IF(AD32>=6,"临界","不合格"))) -> 合格 | AR32: =IF(AH32="","",IF(AH32>=7,"合格",IF(AH32>=6,"临界","不合格"))) -> 合格 | AS32: =IF(AK32="","",IF(AK32>=4,"合格",IF(AK32>=3,"临界","不合格"))) -> 合格 | AT32: =IF(AL32="","",IF(AN32="是","严重失败",IF(AND(S32>=36,Z32>=21,AD32>=7,AH32>=7,AK32>=4,AL32>=80),"生产可用",IF(OR(S32<31.5,Z32<18,AD32<6,AH32<6,AK32<3),"不可用","待复核")))) -> 生产可用
A33: R032 | B33: C06 | C33: P06 | D33: Nano Banana | E33: 3 Lite | F33: 第二轮 | I33: 5 | J33: 4 | K33: 5 | L33: 4 | M33: 4 | N33: 4 | O33: 4 | P33: 4 | Q33: 4 | R33: 4 | S33: =IF(COUNTA(I33:R33)=0,"",I33/5*4+J33/5*4+K33/5*4+L33/4*8+M33/4*5+N33/4*6+O33/4*4+P33/4*4+Q33/4*4+R33/4*2) -> 44.2 | T33: 4 | U33: 4 | V33: 4 | W33: 4 | X33: 4 | Y33: 4 | Z33: =IF(COUNTA(T33:Y33)=0,"",T33/4*7+U33/4*6+V33/4*6+W33/4*4+X33/4*4+Y33/4*3) -> 30 | AA33: 4 | AB33: 4 | AC33: 4 | AD33: =IF(COUNTA(AA33:AC33)=0,"",AA33/4*4+AB33/4*3+AC33/4*3) -> 10 | AE33: 4 | AF33: 4 | AG33: 4 | AH33: =IF(COUNTA(AE33:AG33)=0,"",AE33/4*4+AF33/4*3+AG33/4*3) -> 10 | AI33: 4 | AJ33: 3 | AK33: =IF(COUNTA(AI33:AJ33)=0,"",AI33/4*3+AJ33/4*2) -> 4.5 | AL33: =IF(COUNTA(S33,Z33,AD33,AH33,AK33)<5,"",SUM(S33,Z33,AD33,AH33,AK33)) -> 98.7 | AN33: =IF(AM33="","否","是") -> 否 | AO33: =IF(S33="","",IF(S33>=36,"合格",IF(S33>=31.5,"临界","不合格"))) -> 合格 | AP33: =IF(Z33="","",IF(Z33>=21,"合格",IF(Z33>=18,"临界","不合格"))) -> 合格 | AQ33: =IF(AD33="","",IF(AD33>=7,"合格",IF(AD33>=6,"临界","不合格"))) -> 合格 | AR33: =IF(AH33="","",IF(AH33>=7,"合格",IF(AH33>=6,"临界","不合格"))) -> 合格 | AS33: =IF(AK33="","",IF(AK33>=4,"合格",IF(AK33>=3,"临界","不合格"))) -> 合格 | AT33: =IF(AL33="","",IF(AN33="是","严重失败",IF(AND(S33>=36,Z33>=21,AD33>=7,AH33>=7,AK33>=4,AL33>=80),"生产可用",IF(OR(S33<31.5,Z33<18,AD33<6,AH33<6,AK33<3),"不可用","待复核")))) -> 生产可用
A34: R033 | B34: C06 | C34: P06 | D34: Seedream | E34: 5.0 flash | F34: 第一轮 | I34: 4 | J34: 4 | K34: 4 | L34: 3 | M34: 4 | N34: 4 | O34: 4 | P34: 3 | Q34: 3 | R34: 4 | S34: =IF(COUNTA(I34:R34)=0,"",I34/5*4+J34/5*4+K34/5*4+L34/4*8+M34/4*5+N34/4*6+O34/4*4+P34/4*4+Q34/4*4+R34/4*2) -> 38.6 | T34: 4 | U34: 4 | V34: 3 | W34: 3 | X34: 4 | Y34: 4 | Z34: =IF(COUNTA(T34:Y34)=0,"",T34/4*7+U34/4*6+V34/4*6+W34/4*4+X34/4*4+Y34/4*3) -> 27.5 | AA34: 3 | AB34: 3 | AC34: 3 | AD34: =IF(COUNTA(AA34:AC34)=0,"",AA34/4*4+AB34/4*3+AC34/4*3) -> 7.5 | AE34: 4 | AF34: 4 | AG34: 4 | AH34: =IF(COUNTA(AE34:AG34)=0,"",AE34/4*4+AF34/4*3+AG34/4*3) -> 10 | AI34: 4 | AJ34: 3 | AK34: =IF(COUNTA(AI34:AJ34)=0,"",AI34/4*3+AJ34/4*2) -> 4.5 | AL34: =IF(COUNTA(S34,Z34,AD34,AH34,AK34)<5,"",SUM(S34,Z34,AD34,AH34,AK34)) -> 88.1 | AN34: =IF(AM34="","否","是") -> 否 | AO34: =IF(S34="","",IF(S34>=36,"合格",IF(S34>=31.5,"临界","不合格"))) -> 合格 | AP34: =IF(Z34="","",IF(Z34>=21,"合格",IF(Z34>=18,"临界","不合格"))) -> 合格 | AQ34: =IF(AD34="","",IF(AD34>=7,"合格",IF(AD34>=6,"临界","不合格"))) -> 合格 | AR34: =IF(AH34="","",IF(AH34>=7,"合格",IF(AH34>=6,"临界","不合格"))) -> 合格 | AS34: =IF(AK34="","",IF(AK34>=4,"合格",IF(AK34>=3,"临界","不合格"))) -> 合格 | AT34: =IF(AL34="","",IF(AN34="是","严重失败",IF(AND(S34>=36,Z34>=21,AD34>=7,AH34>=7,AK34>=4,AL34>=80),"生产可用",IF(OR(S34<31.5,Z34<18,AD34<6,AH34<6,AK34<3),"不可用","待复核")))) -> 生产可用
A35: R034 | B35: C06 | C35: P06 | D35: Seedream | E35: 5.0 flash | F35: 第二轮 | I35: 4 | J35: 4 | K35: 4 | L35: 3 | M35: 4 | N35: 4 | O35: 4 | P35: 4 | Q35: 4 | R35: 3 | S35: =IF(COUNTA(I35:R35)=0,"",I35/5*4+J35/5*4+K35/5*4+L35/4*8+M35/4*5+N35/4*6+O35/4*4+P35/4*4+Q35/4*4+R35/4*2) -> 40.1 | T35: 4 | U35: 4 | V35: 4 | W35: 4 | X35: 4 | Y35: 4 | Z35: =IF(COUNTA(T35:Y35)=0,"",T35/4*7+U35/4*6+V35/4*6+W35/4*4+X35/4*4+Y35/4*3) -> 30 | AA35: 3 | AB35: 2 | AC35: 2 | AD35: =IF(COUNTA(AA35:AC35)=0,"",AA35/4*4+AB35/4*3+AC35/4*3) -> 6 | AE35: 4 | AF35: 4 | AG35: 4 | AH35: =IF(COUNTA(AE35:AG35)=0,"",AE35/4*4+AF35/4*3+AG35/4*3) -> 10 | AI35: 4 | AJ35: 3 | AK35: =IF(COUNTA(AI35:AJ35)=0,"",AI35/4*3+AJ35/4*2) -> 4.5 | AL35: =IF(COUNTA(S35,Z35,AD35,AH35,AK35)<5,"",SUM(S35,Z35,AD35,AH35,AK35)) -> 90.6 | AN35: =IF(AM35="","否","是") -> 否 | AO35: =IF(S35="","",IF(S35>=36,"合格",IF(S35>=31.5,"临界","不合格"))) -> 合格 | AP35: =IF(Z35="","",IF(Z35>=21,"合格",IF(Z35>=18,"临界","不合格"))) -> 合格 | AQ35: =IF(AD35="","",IF(AD35>=7,"合格",IF(AD35>=6,"临界","不合格"))) -> 临界 | AR35: =IF(AH35="","",IF(AH35>=7,"合格",IF(AH35>=6,"临界","不合格"))) -> 合格 | AS35: =IF(AK35="","",IF(AK35>=4,"合格",IF(AK35>=3,"临界","不合格"))) -> 合格 | AT35: =IF(AL35="","",IF(AN35="是","严重失败",IF(AND(S35>=36,Z35>=21,AD35>=7,AH35>=7,AK35>=4,AL35>=80),"生产可用",IF(OR(S35<31.5,Z35<18,AD35<6,AH35<6,AK35<3),"不可用","待复核")))) -> 待复核
A36: R035 | B36: C06 | C36: P06 | D36: GPT image | E36: 2.5 | F36: 第一轮 | I36: 4 | J36: 3 | K36: 4 | L36: 4 | M36: 4 | N36: 4 | O36: 4 | P36: 4 | Q36: 3 | R36: 4 | S36: =IF(COUNTA(I36:R36)=0,"",I36/5*4+J36/5*4+K36/5*4+L36/4*8+M36/4*5+N36/4*6+O36/4*4+P36/4*4+Q36/4*4+R36/4*2) -> 40.8 | T36: 4 | U36: 4 | V36: 4 | W36: 4 | X36: 4 | Y36: 4 | Z36: =IF(COUNTA(T36:Y36)=0,"",T36/4*7+U36/4*6+V36/4*6+W36/4*4+X36/4*4+Y36/4*3) -> 30 | AA36: 0 | AB36: 4 | AC36: 4 | AD36: =IF(COUNTA(AA36:AC36)=0,"",AA36/4*4+AB36/4*3+AC36/4*3) -> 6 | AE36: 4 | AF36: 4 | AG36: 4 | AH36: =IF(COUNTA(AE36:AG36)=0,"",AE36/4*4+AF36/4*3+AG36/4*3) -> 10 | AI36: 4 | AJ36: 3 | AK36: =IF(COUNTA(AI36:AJ36)=0,"",AI36/4*3+AJ36/4*2) -> 4.5 | AL36: =IF(COUNTA(S36,Z36,AD36,AH36,AK36)<5,"",SUM(S36,Z36,AD36,AH36,AK36)) -> 91.3 | AN36: =IF(AM36="","否","是") -> 否 | AO36: =IF(S36="","",IF(S36>=36,"合格",IF(S36>=31.5,"临界","不合格"))) -> 合格 | AP36: =IF(Z36="","",IF(Z36>=21,"合格",IF(Z36>=18,"临界","不合格"))) -> 合格 | AQ36: =IF(AD36="","",IF(AD36>=7,"合格",IF(AD36>=6,"临界","不合格"))) -> 临界 | AR36: =IF(AH36="","",IF(AH36>=7,"合格",IF(AH36>=6,"临界","不合格"))) -> 合格 | AS36: =IF(AK36="","",IF(AK36>=4,"合格",IF(AK36>=3,"临界","不合格"))) -> 合格 | AT36: =IF(AL36="","",IF(AN36="是","严重失败",IF(AND(S36>=36,Z36>=21,AD36>=7,AH36>=7,AK36>=4,AL36>=80),"生产可用",IF(OR(S36<31.5,Z36<18,AD36<6,AH36<6,AK36<3),"不可用","待复核")))) -> 待复核
A37: R036 | B37: C06 | C37: P06 | D37: GPT image | E37: 2.5 | F37: 第二轮 | I37: 4 | J37: 3 | K37: 4 | L37: 4 | M37: 4 | N37: 4 | O37: 4 | P37: 4 | Q37: 3 | R37: 4 | S37: =IF(COUNTA(I37:R37)=0,"",I37/5*4+J37/5*4+K37/5*4+L37/4*8+M37/4*5+N37/4*6+O37/4*4+P37/4*4+Q37/4*4+R37/4*2) -> 40.8 | T37: 4 | U37: 4 | V37: 4 | W37: 4 | X37: 4 | Y37: 4 | Z37: =IF(COUNTA(T37:Y37)=0,"",T37/4*7+U37/4*6+V37/4*6+W37/4*4+X37/4*4+Y37/4*3) -> 30 | AA37: 0 | AB37: 4 | AC37: 4 | AD37: =IF(COUNTA(AA37:AC37)=0,"",AA37/4*4+AB37/4*3+AC37/4*3) -> 6 | AE37: 4 | AF37: 4 | AG37: 4 | AH37: =IF(COUNTA(AE37:AG37)=0,"",AE37/4*4+AF37/4*3+AG37/4*3) -> 10 | AI37: 4 | AJ37: 3 | AK37: =IF(COUNTA(AI37:AJ37)=0,"",AI37/4*3+AJ37/4*2) -> 4.5 | AL37: =IF(COUNTA(S37,Z37,AD37,AH37,AK37)<5,"",SUM(S37,Z37,AD37,AH37,AK37)) -> 91.3 | AN37: =IF(AM37="","否","是") -> 否 | AO37: =IF(S37="","",IF(S37>=36,"合格",IF(S37>=31.5,"临界","不合格"))) -> 合格 | AP37: =IF(Z37="","",IF(Z37>=21,"合格",IF(Z37>=18,"临界","不合格"))) -> 合格 | AQ37: =IF(AD37="","",IF(AD37>=7,"合格",IF(AD37>=6,"临界","不合格"))) -> 临界 | AR37: =IF(AH37="","",IF(AH37>=7,"合格",IF(AH37>=6,"临界","不合格"))) -> 合格 | AS37: =IF(AK37="","",IF(AK37>=4,"合格",IF(AK37>=3,"临界","不合格"))) -> 合格 | AT37: =IF(AL37="","",IF(AN37="是","严重失败",IF(AND(S37>=36,Z37>=21,AD37>=7,AH37>=7,AK37>=4,AL37>=80),"生产可用",IF(OR(S37<31.5,Z37<18,AD37<6,AH37<6,AK37<3),"不可用","待复核")))) -> 待复核
A38: R037 | B38: C07 | C38: P07 | D38: Nano Banana | E38: 3 Lite | F38: 第一轮 | I38: 3 | J38: 5 | K38: 5 | L38: 4 | M38: 4 | N38: 4 | O38: 4 | P38: 4 | Q38: 4 | R38: 4 | S38: =IF(COUNTA(I38:R38)=0,"",I38/5*4+J38/5*4+K38/5*4+L38/4*8+M38/4*5+N38/4*6+O38/4*4+P38/4*4+Q38/4*4+R38/4*2) -> 43.4 | T38: 4 | U38: 4 | V38: 4 | W38: 4 | X38: 4 | Y38: 4 | Z38: =IF(COUNTA(T38:Y38)=0,"",T38/4*7+U38/4*6+V38/4*6+W38/4*4+X38/4*4+Y38/4*3) -> 30 | AA38: 4 | AB38: 4 | AC38: 4 | AD38: =IF(COUNTA(AA38:AC38)=0,"",AA38/4*4+AB38/4*3+AC38/4*3) -> 10 | AE38: 4 | AF38: 4 | AG38: 4 | AH38: =IF(COUNTA(AE38:AG38)=0,"",AE38/4*4+AF38/4*3+AG38/4*3) -> 10 | AI38: 4 | AJ38: 3 | AK38: =IF(COUNTA(AI38:AJ38)=0,"",AI38/4*3+AJ38/4*2) -> 4.5 | AL38: =IF(COUNTA(S38,Z38,AD38,AH38,AK38)<5,"",SUM(S38,Z38,AD38,AH38,AK38)) -> 97.9 | AN38: =IF(AM38="","否","是") -> 否 | AO38: =IF(S38="","",IF(S38>=36,"合格",IF(S38>=31.5,"临界","不合格"))) -> 合格 | AP38: =IF(Z38="","",IF(Z38>=21,"合格",IF(Z38>=18,"临界","不合格"))) -> 合格 | AQ38: =IF(AD38="","",IF(AD38>=7,"合格",IF(AD38>=6,"临界","不合格"))) -> 合格 | AR38: =IF(AH38="","",IF(AH38>=7,"合格",IF(AH38>=6,"临界","不合格"))) -> 合格 | AS38: =IF(AK38="","",IF(AK38>=4,"合格",IF(AK38>=3,"临界","不合格"))) -> 合格 | AT38: =IF(AL38="","",IF(AN38="是","严重失败",IF(AND(S38>=36,Z38>=21,AD38>=7,AH38>=7,AK38>=4,AL38>=80),"生产可用",IF(OR(S38<31.5,Z38<18,AD38<6,AH38<6,AK38<3),"不可用","待复核")))) -> 生产可用
